Workbook

Sheet TS
A1: Survey Station | B1: Survey Elevation | C1: Pipe Wall Thickness | D1: Survey Joint Length | E1: Volume | F1: Cumulative Volume | G1: Selected Material Type | H1: Class Location | I1: Pipe Wall Actual | J1: Max. Pressure | K1: Min. Pressure | L1: Elevation Diff from High | M1: Test Pressure | N1: Stationing | O1: Elevation | P1: Elev Diff | Q1: Max Press | R1: Min Press | S1: Minimum Test Press | T1: Maximum Test Pressure | U1: SMYS | V1: High Elev Pt to end (ft) | W1: Dewater Pressure (psi) | X1: Air Vol (SCF) | Y1: Air Vol (SCF)*1000 | Z1: Min Air Vol (SCF)*1000 | AA1: High Elev Pt to end (ft) | AB1: Calc. Backpressure (psi) | AC1: Fill Pressure | AD1: Minimum backpressure | AE1: Volume | AF1: Cumulative Volume
A2: 95899.92 | B2: 825.1845 | C2: 0.6 | D2: 0 | E2: =(PI()/4*(42/12-(2*C44/12))^2)*(D2)*7.48 -> 0 | F2: =SUM(E$2:E2) -> 0 | G2: =IF(C2=0.72,12,IF(C2=1,11,IF(C2=0.825,10,IF(C2=0.6,1,IF(C2=0.864,2,IF(C2=0.888,3)))))) -> 1 | H2: 1 | I2: =C2 -> 0.6 | J2: =VLOOKUP(G2,Inputs!$L$3:$P$15,5,FALSE) -> 2000 | K2: =IF(H2=1,1825,IF(H2=2,1825,2220)) -> 1825 | L2: =Inputs!$P$8-B2 -> 113.0065 | M2: =Inputs!$Q$8+L2*0.433 -> 1873.9318 | N2: =A2 -> 95899.92 | O2: =B2 -> 825.1845 | P2: =IF(O2="","",Inputs!$C$5-O2) -> 0 | Q2: =IF(N2="","",TS!J2) -> 2000 | R2: =IF(N2="","",TS!K2) -> 1825 | S2: =Inputs!$H$5+TS!P2*0.4333 -> 1874.9657 | T2: =Inputs!$G$5+TS!P2*0.4333 -> 1889.9657 | U2: =T2/(140000*C2/42) -> 0.94498286 | V2: =O2-MAX(O2:O177) -> 0 | W2: =-(V2)*0.433 -> 0 | X2: =((PI()*((42-2*'Gen Calcs'!$E$13)^2)/4)/144)*(A45-#REF!)*(W2+14.7)/14.7 -> #REF! | Y2: =X2/1000 -> #REF! | Z2: =IF(Y2>#REF!,Y2,#REF!) -> #REF! | AA2: =MAX(B$2:B2)-B2 -> 0 | AB2: =AA2*0.433 -> 0 | AC2: =((MAX(O$2:O$1348)-O2)-(MAX(O$2:O$1348)-O2))*0.433+AD2 -> 95 | AD2: 95 | AE2: =PI()*(((42-2*C2)/12)^2/4)*D2 -> 0 | AF2: =SUM(AE$2:AE2) -> 0 | AG2: =AF$1391-AF2 -> 1173729.9
A3: 95999.92 | B3: 822.0039 | C3: 0.6 | D3: =A3-A2 -> 100 | E3: =(PI()/4*(42/12-(2*C45/12))^2)*(D3)*7.48 -> 6791.2437 | F3: =SUM(E$2:E3) -> 6791.2437 | G3: =IF(C3=0.72,12,IF(C3=1,11,IF(C3=0.825,10,IF(C3=0.6,1,IF(C3=0.864,2,IF(C3=0.888,3)))))) -> 1 | H3: 1 | I3: =C3 -> 0.6 | J3: =VLOOKUP(G3,Inputs!$L$3:$P$15,5,FALSE) -> 2000 | K3: =IF(H3=1,1825,IF(H3=2,1825,2220)) -> 1825 | L3: =Inputs!$P$8-B3 -> 116.1871 | M3: =Inputs!$Q$8+L3*0.433 -> 1875.309 | N3: =A3 -> 95999.92 | O3: =B3 -> 822.0039 | P3: =IF(O3="","",Inputs!$C$5-O3) -> 3.1806 | Q3: =IF(N3="","",TS!J3) -> 2000 | R3: =IF(N3="","",TS!K3) -> 1825 | S3: =Inputs!$H$5+TS!P3*0.4333 -> 1876.3439 | T3: =Inputs!$G$5+TS!P3*0.4333 -> 1891.3439 | U3: =T3/(140000*C3/42) -> 0.94567194 | V3: =O3-MAX(O3:O177) -> 0 | W3: =-(V3)*0.433 -> 0 | X3: =((PI()*((42-2*'Gen Calcs'!$E$13)^2)/4)/144)*(A46-#REF!)*(W3+14.7)/14.7 -> #REF! | Y3: =X3/1000 -> #REF! | Z3: =IF(Y3>Z2,Y3,Z2) -> #REF! | AA3: =MAX(B$2:B3)-B3 -> 3.1806 | AB3: =AA3*0.433 -> 1.3771998 | AC3: =((MAX(O$2:O$1348)-O3)-(MAX(O$2:O$1348)-O3))*0.433+AD3 -> 95.073543 | AD3: =(AD$2*AF$1391)/AG3 -> 95.073543 | AE3: =PI()*(((42-2*C3)/12)^2/4)*D3 -> 907.92028 | AF3: =SUM(AE$2:AE3) -> 907.92028 | AG3: =AF$1391-AF3 -> 1172822
A4: 96099.92 | B4: 818.5449 | C4: 0.6 | D4: =A4-A3 -> 100 | E4: =(PI()/4*(42/12-(2*C46/12))^2)*(D4)*7.48 -> 6616.6077 | F4: =SUM(E$2:E4) -> 13407.851 | G4: =IF(C4=0.72,12,IF(C4=1,11,IF(C4=0.825,10,IF(C4=0.6,1,IF(C4=0.864,2,IF(C4=0.888,3)))))) -> 1 | H4: 1 | I4: =C4 -> 0.6 | J4: =VLOOKUP(G4,Inputs!$L$3:$P$15,5,FALSE) -> 2000 | K4: =IF(H4=1,1825,IF(H4=2,1825,2220)) -> 1825 | L4: =Inputs!$P$8-B4 -> 119.6461 | M4: =Inputs!$Q$8+L4*0.433 -> 1876.8068 | N4: =A4 -> 96099.92 | O4: =B4 -> 818.5449 | P4: =IF(O4="","",Inputs!$C$5-O4) -> 6.6396 | Q4: =IF(N4="","",TS!J4) -> 2000 | R4: =IF(N4="","",TS!K4) -> 1825 | S4: =Inputs!$H$5+TS!P4*0.4333 -> 1877.8427 | T4: =Inputs!$G$5+TS!P4*0.4333 -> 1892.8427 | U4: =T4/(140000*C4/42) -> 0.94642133 | V4: =O4-MAX(O4:O177) -> 0 | W4: =-(V4)*0.433 -> 0 | X4: =((PI()*((42-2*'Gen Calcs'!$E$13)^2)/4)/144)*(A47-#REF!)*(W4+14.7)/14.7 -> #REF! | Y4: =X4/1000 -> #REF! | Z4: =IF(Y4>Z3,Y4,Z3) -> #REF! | AA4: =MAX(B$2:B4)-B4 -> 6.6396 | AB4: =AA4*0.433 -> 2.8749468 | AC4: =((MAX(O$2:O$1348)-O4)-(MAX(O$2:O$1348)-O4))*0.433+AD4 -> 95.147199 | AD4: =(AD$2*AF$1391)/AG4 -> 95.147199 | AE4: =PI()*(((42-2*C4)/12)^2/4)*D4 -> 907.92028 | AF4: =SUM(AE$2:AE4) -> 1815.8406 | AG4: =AF$1391-AF4 -> 1171914.1
A5: 96199.92 | B5: 814.7277 | C5: 0.6 | D5: =A5-A4 -> 100 | E5: =(PI()/4*(42/12-(2*C47/12))^2)*(D5)*7.48 -> 6791.2437 | F5: =SUM(E$2:E5) -> 20199.095 | G5: =IF(C5=0.72,12,IF(C5=1,11,IF(C5=0.825,10,IF(C5=0.6,1,IF(C5=0.864,2,IF(C5=0.888,3)))))) -> 1 | H5: 1 | I5: =C5 -> 0.6 | J5: =VLOOKUP(G5,Inputs!$L$3:$P$15,5,FALSE) -> 2000 | K5: =IF(H5=1,1825,IF(H5=2,1825,2220)) -> 1825 | L5: =Inputs!$P$8-B5 -> 123.4633 | M5: =Inputs!$Q$8+L5*0.433 -> 1878.4596 | N5: =A5 -> 96199.92 | O5: =B5 -> 814.7277 | P5: =IF(O5="","",Inputs!$C$5-O5) -> 10.4568 | Q5: =IF(N5="","",TS!J5) -> 2000 | R5: =IF(N5="","",TS!K5) -> 1825 | S5: =Inputs!$H$5+TS!P5*0.4333 -> 1879.4966 | T5: =Inputs!$G$5+TS!P5*0.4333 -> 1894.4966 | U5: =T5/(140000*C5/42) -> 0.94724832 | V5: =O5-MAX(O5:O177) -> 0 | W5: =-(V5)*0.433 -> 0 | X5: =((PI()*((42-2*'Gen Calcs'!$E$13)^2)/4)/144)*(A48-#REF!)*(W5+14.7)/14.7 -> #REF! | Y5: =X5/1000 -> #REF! | Z5: =IF(Y5>Z4,Y5,Z4) -> #REF! | AA5: =MAX(B$2:B5)-B5 -> 10.4568 | AB5: =AA5*0.433 -> 4.5277944 | AC5: =((MAX(O$2:O$1348)-O5)-(MAX(O$2:O$1348)-O5))*0.433+AD5 -> 95.22097 | AD5: =(AD$2*AF$1391)/AG5 -> 95.22097 | AE5: =PI()*(((42-2*C5)/12)^2/4)*D5 -> 907.92028 | AF5: =SUM(AE$2:AE5) -> 2723.7608 | AG5: =AF$1391-AF5 -> 1171006.1
A6: 96299.92 | B6: 812.4204 | C6: 0.6 | D6: =A6-A5 -> 100 | E6: =(PI()/4*(42/12-(2*C48/12))^2)*(D6)*7.48 -> 6791.2437 | F6: =SUM(E$2:E6) -> 26990.339 | G6: =IF(C6=0.72,12,IF(C6=1,11,IF(C6=0.825,10,IF(C6=0.6,1,IF(C6=0.864,2,IF(C6=0.888,3)))))) -> 1 | H6: 1 | I6: =C6 -> 0.6 | J6: =VLOOKUP(G6,Inputs!$L$3:$P$15,5,FALSE) -> 2000 | K6: =IF(H6=1,1825,IF(H6=2,1825,2220)) -> 1825 | L6: =Inputs!$P$8-B6 -> 125.7706 | M6: =Inputs!$Q$8+L6*0.433 -> 1879.4587 | N6: =A6 -> 96299.92 | O6: =B6 -> 812.4204 | P6: =IF(O6="","",Inputs!$C$5-O6) -> 12.7641 | Q6: =IF(N6="","",TS!J6) -> 2000 | R6: =IF(N6="","",TS!K6) -> 1825 | S6: =Inputs!$H$5+TS!P6*0.4333 -> 1880.4964 | T6: =Inputs!$G$5+TS!P6*0.4333 -> 1895.4964 | U6: =T6/(140000*C6/42) -> 0.9477482 | V6: =O6-MAX(O6:O177) -> -0.2078 | W6: =-(V6)*0.433 -> 0.0899774 | X6: =((PI()*((42-2*'Gen Calcs'!$E$13)^2)/4)/144)*(A49-#REF!)*(W6+14.7)/14.7 -> #REF! | Y6: =X6/1000 -> #REF! | Z6: =IF(Y6>Z5,Y6,Z5) -> #REF! | AA6: =MAX(B$2:B6)-B6 -> 12.7641 | AB6: =AA6*0.433 -> 5.5268553 | AC6: =((MAX(O$2:O$1348)-O6)-(MAX(O$2:O$1348)-O6))*0.433+AD6 -> 95.294855 | AD6: =(AD$2*AF$1391)/AG6 -> 95.294855 | AE6: =PI()*(((42-2*C6)/12)^2/4)*D6 -> 907.92028 | AF6: =SUM(AE$2:AE6) -> 3631.6811 | AG6: =AF$1391-AF6 -> 1170098.2
A7: 96399.92 | B7: 808.4569 | C7: 0.6 | D7: =A7-A6 -> 100 | E7: =(PI()/4*(42/12-(2*C49/12))^2)*(D7)*7.48 -> 6791.2437 | F7: =SUM(E$2:E7) -> 33781.582 | G7: =IF(C7=0.72,12,IF(C7=1,11,IF(C7=0.825,10,IF(C7=0.6,1,IF(C7=0.864,2,IF(C7=0.888,3)))))) -> 1 | H7: 1 | I7: =C7 -> 0.6 | J7: =VLOOKUP(G7,Inputs!$L$3:$P$15,5,FALSE) -> 2000 | K7: =IF(H7=1,1825,IF(H7=2,1825,2220)) -> 1825 | L7: =Inputs!$P$8-B7 -> 129.7341 | M7: =Inputs!$Q$8+L7*0.433 -> 1881.1749 | N7: =A7 -> 96399.92 | O7: =B7 -> 808.4569 | P7: =IF(O7="","",Inputs!$C$5-O7) -> 16.7276 | Q7: =IF(N7="","",TS!J7) -> 2000 | R7: =IF(N7="","",TS!K7) -> 1825 | S7: =Inputs!$H$5+TS!P7*0.4333 -> 1882.2138 | T7: =Inputs!$G$5+TS!P7*0.4333 -> 1897.2138 | U7: =T7/(140000*C7/42) -> 0.94860689 | V7: =O7-MAX(O7:O177) -> -4.1713 | W7: =-(V7)*0.433 -> 1.8061729 | X7: =((PI()*((42-2*'Gen Calcs'!$E$13)^2)/4)/144)*(A50-#REF!)*(W7+14.7)/14.7 -> #REF! | Y7: =X7/1000 -> #REF! | Z7: =IF(Y7>Z6,Y7,Z6) -> #REF! | AA7: =MAX(B$2:B7)-B7 -> 16.7276 | AB7: =AA7*0.433 -> 7.2430508 | AC7: =((MAX(O$2:O$1348)-O7)-(MAX(O$2:O$1348)-O7))*0.433+AD7 -> 95.368855 | AD7: =(AD$2*AF$1391)/AG7 -> 95.368855 | AE7: =PI()*(((42-2*C7)/12)^2/4)*D7 -> 907.92028 | AF7: =SUM(AE$2:AE7) -> 4539.6014 | AG7: =AF$1391-AF7 -> 1169190.3
A8: 96499.92 | B8: 805.6716 | C8: 0.6 | D8: =A8-A7 -> 100 | E8: =(PI()/4*(42/12-(2*C50/12))^2)*(D8)*7.48 -> 6791.2437 | F8: =SUM(E$2:E8) -> 40572.826 | G8: =IF(C8=0.72,12,IF(C8=1,11,IF(C8=0.825,10,IF(C8=0.6,1,IF(C8=0.864,2,IF(C8=0.888,3)))))) -> 1 | H8: 1 | I8: =C8 -> 0.6 | J8: =VLOOKUP(G8,Inputs!$L$3:$P$15,5,FALSE) -> 2000 | K8: =IF(H8=1,1825,IF(H8=2,1825,2220)) -> 1825 | L8: =Inputs!$P$8-B8 -> 132.5194 | M8: =Inputs!$Q$8+L8*0.433 -> 1882.3809 | N8: =A8 -> 96499.92 | O8: =B8 -> 805.6716 | P8: =IF(O8="","",Inputs!$C$5-O8) -> 19.5129 | Q8: =IF(N8="","",TS!J8) -> 2000 | R8: =IF(N8="","",TS!K8) -> 1825 | S8: =Inputs!$H$5+TS!P8*0.4333 -> 1883.4207 | T8: =Inputs!$G$5+TS!P8*0.4333 -> 1898.4207 | U8: =T8/(140000*C8/42) -> 0.94921033 | V8: =O8-MAX(O8:O177) -> -6.9566 | W8: =-(V8)*0.433 -> 3.0122078 | X8: =((PI()*((42-2*'Gen Calcs'!$E$13)^2)/4)/144)*(A51-#REF!)*(W8+14.7)/14.7 -> #REF! | Y8: =X8/1000 -> #REF! | Z8: =IF(Y8>Z7,Y8,Z7) -> #REF! | AA8: =MAX(B$2:B8)-B8 -> 19.5129 | AB8: =AA8*0.433 -> 8.4490857 | AC8: =((MAX(O$2:O$1348)-O8)-(MAX(O$2:O$1348)-O8))*0.433+AD8 -> 95.44297 | AD8: =(AD$2*AF$1391)/AG8 -> 95.44297 | AE8: =PI()*(((42-2*C8)/12)^2/4)*D8 -> 907.92028 | AF8: =SUM(AE$2:AE8) -> 5447.5217 | AG8: =AF$1391-AF8 -> 1168282.4
A9: 96599.92 | B9: 803.4641 | C9: 0.6 | D9: =A9-A8 -> 100 | E9: =(PI()/4*(42/12-(2*C51/12))^2)*(D9)*7.48 -> 6791.2437 | F9: =SUM(E$2:E9) -> 47364.07 | G9: =IF(C9=0.72,12,IF(C9=1,11,IF(C9=0.825,10,IF(C9=0.6,1,IF(C9=0.864,2,IF(C9=0.888,3)))))) -> 1 | H9: 1 | I9: =C9 -> 0.6 | J9: =VLOOKUP(G9,Inputs!$L$3:$P$15,5,FALSE) -> 2000 | K9: =IF(H9=1,1825,IF(H9=2,1825,2220)) -> 1825 | L9: =Inputs!$P$8-B9 -> 134.7269 | M9: =Inputs!$Q$8+L9*0.433 -> 1883.3367 | N9: =A9 -> 96599.92 | O9: =B9 -> 803.4641 | P9: =IF(O9="","",Inputs!$C$5-O9) -> 21.7204 | Q9: =IF(N9="","",TS!J9) -> 2000 | R9: =IF(N9="","",TS!K9) -> 1825 | S9: =Inputs!$H$5+TS!P9*0.4333 -> 1884.3772 | T9: =Inputs!$G$5+TS!P9*0.4333 -> 1899.3772 | U9: =T9/(140000*C9/42) -> 0.94968858 | V9: =O9-MAX(O9:O177) -> -9.1641 | W9: =-(V9)*0.433 -> 3.9680553 | X9: =((PI()*((42-2*'Gen Calcs'!$E$13)^2)/4)/144)*(A52-#REF!)*(W9+14.7)/14.7 -> #REF! | Y9: =X9/1000 -> #REF! | Z9: =IF(Y9>Z8,Y9,Z8) -> #REF! | AA9: =MAX(B$2:B9)-B9 -> 21.7204 | AB9: =AA9*0.433 -> 9.4049332 | AC9: =((MAX(O$2:O$1348)-O9)-(MAX(O$2:O$1348)-O9))*0.433+AD9 -> 95.517201 | AD9: =(AD$2*AF$1391)/AG9 -> 95.517201 | AE9: =PI()*(((42-2*C9)/12)^2/4)*D9 -> 907.92028 | AF9: =SUM(AE$2:AE9) -> 6355.4419 | AG9: =AF$1391-AF9 -> 1167374.5
A10: 96699.92 | B10: 802.625 | C10: 0.6 | D10: =A10-A9 -> 100 | E10: =(PI()/4*(42/12-(2*C52/12))^2)*(D10)*7.48 -> 6791.2437 | F10: =SUM(E$2:E10) -> 54155.313 | G10: =IF(C10=0.72,12,IF(C10=1,11,IF(C10=0.825,10,IF(C10=0.6,1,IF(C10=0.864,2,IF(C10=0.888,3)))))) -> 1 | H10: 1 | I10: =C10 -> 0.6 | J10: =VLOOKUP(G10,Inputs!$L$3:$P$15,5,FALSE) -> 2000 | K10: =IF(H10=1,1825,IF(H10=2,1825,2220)) -> 1825 | L10: =Inputs!$P$8-B10 -> 135.566 | M10: =Inputs!$Q$8+L10*0.433 -> 1883.7001 | N10: =A10 -> 96699.92 | O10: =B10 -> 802.625 | P10: =IF(O10="","",Inputs!$C$5-O10) -> 22.5595 | Q10: =IF(N10="","",TS!J10) -> 2000 | R10: =IF(N10="","",TS!K10) -> 1825 | S10: =Inputs!$H$5+TS!P10*0.4333 -> 1884.7407 | T10: =Inputs!$G$5+TS!P10*0.4333 -> 1899.7407 | U10: =T10/(140000*C10/42) -> 0.94987037 | V10: =O10-MAX(O10:O177) -> -10.0032 | W10: =-(V10)*0.433 -> 4.3313856 | X10: =((PI()*((42-2*'Gen Calcs'!$E$13)^2)/4)/144)*(A53-#REF!)*(W10+14.7)/14.7 -> #REF! | Y10: =X10/1000 -> #REF! | Z10: =IF(Y10>Z9,Y10,Z9) -> #REF! | AA10: =MAX(B$2:B10)-B10 -> 22.5595 | AB10: =AA10*0.433 -> 9.7682635 | AC10: =((MAX(O$2:O$1348)-O10)-(MAX(O$2:O$1348)-O10))*0.433+AD10 -> 95.591547 | AD10: =(AD$2*AF$1391)/AG10 -> 95.591547 | AE10: =PI()*(((42-2*C10)/12)^2/4)*D10 -> 907.92028 | AF10: =SUM(AE$2:AE10) -> 7263.3622 | AG10: =AF$1391-AF10 -> 1166466.5
A11: 96799.92 | B11: 802.1073 | C11: 0.6 | D11: =A11-A10 -> 100 | E11: =(PI()/4*(42/12-(2*C53/12))^2)*(D11)*7.48 -> 6791.2437 | F11: =SUM(E$2:E11) -> 60946.557 | G11: =IF(C11=0.72,12,IF(C11=1,11,IF(C11=0.825,10,IF(C11=0.6,1,IF(C11=0.864,2,IF(C11=0.888,3)))))) -> 1 | H11: 1 | I11: =C11 -> 0.6 | J11: =VLOOKUP(G11,Inputs!$L$3:$P$15,5,FALSE) -> 2000 | K11: =IF(H11=1,1825,IF(H11=2,1825,2220)) -> 1825 | L11: =Inputs!$P$8-B11 -> 136.0837 | M11: =Inputs!$Q$8+L11*0.433 -> 1883.9242 | N11: =A11 -> 96799.92 | O11: =B11 -> 802.1073 | P11: =IF(O11="","",Inputs!$C$5-O11) -> 23.0772 | Q11: =IF(N11="","",TS!J11) -> 2000 | R11: =IF(N11="","",TS!K11) -> 1825 | S11: =Inputs!$H$5+TS!P11*0.4333 -> 1884.9651 | T11: =Inputs!$G$5+TS!P11*0.4333 -> 1899.9651 | U11: =T11/(140000*C11/42) -> 0.94998253 | V11: =O11-MAX(O11:O177) -> -10.5209 | W11: =-(V11)*0.433 -> 4.5555497 | X11: =((PI()*((42-2*'Gen Calcs'!$E$13)^2)/4)/144)*(A54-#REF!)*(W11+14.7)/14.7 -> #REF! | Y11: =X11/1000 -> #REF! | Z11: =IF(Y11>Z10,Y11,Z10) -> #REF! | AA11: =MAX(B$2:B11)-B11 -> 23.0772 | AB11: =AA11*0.433 -> 9.9924276 | AC11: =((MAX(O$2:O$1348)-O11)-(MAX(O$2:O$1348)-O11))*0.433+AD11 -> 95.666008 | AD11: =(AD$2*AF$1391)/AG11 -> 95.666008 | AE11: =PI()*(((42-2*C11)/12)^2/4)*D11 -> 907.92028 | AF11: =SUM(AE$2:AE11) -> 8171.2825 | AG11: =AF$1391-AF11 -> 1165558.6
A12: 96899.92 | B12: 801.9379 | C12: 0.6 | D12: =A12-A11 -> 100 | E12: =(PI()/4*(42/12-(2*C54/12))^2)*(D12)*7.48 -> 6791.2437 | F12: =SUM(E$2:E12) -> 67737.801 | G12: =IF(C12=0.72,12,IF(C12=1,11,IF(C12=0.825,10,IF(C12=0.6,1,IF(C12=0.864,2,IF(C12=0.888,3)))))) -> 1 | H12: 1 | I12: =C12 -> 0.6 | J12: =VLOOKUP(G12,Inputs!$L$3:$P$15,5,FALSE) -> 2000 | K12: =IF(H12=1,1825,IF(H12=2,1825,2220)) -> 1825 | L12: =Inputs!$P$8-B12 -> 136.2531 | M12: =Inputs!$Q$8+L12*0.433 -> 1883.9976 | N12: =A12 -> 96899.92 | O12: =B12 -> 801.9379 | P12: =IF(O12="","",Inputs!$C$5-O12) -> 23.2466 | Q12: =IF(N12="","",TS!J12) -> 2000 | R12: =IF(N12="","",TS!K12) -> 1825 | S12: =Inputs!$H$5+TS!P12*0.4333 -> 1885.0385 | T12: =Inputs!$G$5+TS!P12*0.4333 -> 1900.0385 | U12: =T12/(140000*C12/42) -> 0.95001923 | V12: =O12-MAX(O12:O177) -> -10.6903 | W12: =-(V12)*0.433 -> 4.6288999 | X12: =((PI()*((42-2*'Gen Calcs'!$E$13)^2)/4)/144)*(A55-#REF!)*(W12+14.7)/14.7 -> #REF! | Y12: =X12/1000 -> #REF! | Z12: =IF(Y12>Z11,Y12,Z11) -> #REF! | AA12: =MAX(B$2:B12)-B12 -> 23.2466 | AB12: =AA12*0.433 -> 10.065778 | AC12: =((MAX(O$2:O$1348)-O12)-(MAX(O$2:O$1348)-O12))*0.433+AD12 -> 95.740586 | AD12: =(AD$2*AF$1391)/AG12 -> 95.740586 | AE12: =PI()*(((42-2*C12)/12)^2/4)*D12 -> 907.92028 | AF12: =SUM(AE$2:AE12) -> 9079.2028 | AG12: =AF$1391-AF12 -> 1164650.7
A13: 96999.92 | B13: 804.2642 | C13: 0.6 | D13: =A13-A12 -> 100 | E13: =(PI()/4*(42/12-(2*C55/12))^2)*(D13)*7.48 -> 6791.2437 | F13: =SUM(E$2:E13) -> 74529.044 | G13: =IF(C13=0.72,12,IF(C13=1,11,IF(C13=0.825,10,IF(C13=0.6,1,IF(C13=0.864,2,IF(C13=0.888,3)))))) -> 1 | H13: 1 | I13: =C13 -> 0.6 | J13: =VLOOKUP(G13,Inputs!$L$3:$P$15,5,FALSE) -> 2000 | K13: =IF(H13=1,1825,IF(H13=2,1825,2220)) -> 1825 | L13: =Inputs!$P$8-B13 -> 133.9268 | M13: =Inputs!$Q$8+L13*0.433 -> 1882.9903 | N13: =A13 -> 96999.92 | O13: =B13 -> 804.2642 | P13: =IF(O13="","",Inputs!$C$5-O13) -> 20.9203 | Q13: =IF(N13="","",TS!J13) -> 2000 | R13: =IF(N13="","",TS!K13) -> 1825 | S13: =Inputs!$H$5+TS!P13*0.4333 -> 1884.0305 | T13: =Inputs!$G$5+TS!P13*0.4333 -> 1899.0305 | U13: =T13/(140000*C13/42) -> 0.94951524 | V13: =O13-MAX(O13:O177) -> -8.364 | W13: =-(V13)*0.433 -> 3.621612 | X13: =((PI()*((42-2*'Gen Calcs'!$E$13)^2)/4)/144)*(A56-#REF!)*(W13+14.7)/14.7 -> #REF! | Y13: =X13/1000 -> #REF! | Z13: =IF(Y13>Z12,Y13,Z12) -> #REF! | AA13: =MAX(B$2:B13)-B13 -> 20.9203 | AB13: =AA13*0.433 -> 9.0584899 | AC13: =((MAX(O$2:O$1348)-O13)-(MAX(O$2:O$1348)-O13))*0.433+AD13 -> 95.81528 | AD13: =(AD$2*AF$1391)/AG13 -> 95.81528 | AE13: =PI()*(((42-2*C13)/12)^2/4)*D13 -> 907.92028 | AF13: =SUM(AE$2:AE13) -> 9987.123 | AG13: =AF$1391-AF13 -> 1163742.8
A14: 97099.92 | B14: 807.3161 | C14: 0.6 | D14: =A14-A13 -> 100 | E14: =(PI()/4*(42/12-(2*C56/12))^2)*(D14)*7.48 -> 6791.2437 | F14: =SUM(E$2:E14) -> 81320.288 | G14: =IF(C14=0.72,12,IF(C14=1,11,IF(C14=0.825,10,IF(C14=0.6,1,IF(C14=0.864,2,IF(C14=0.888,3)))))) -> 1 | H14: 1 | I14: =C14 -> 0.6 | J14: =VLOOKUP(G14,Inputs!$L$3:$P$15,5,FALSE) -> 2000 | K14: =IF(H14=1,1825,IF(H14=2,1825,2220)) -> 1825 | L14: =Inputs!$P$8-B14 -> 130.8749 | M14: =Inputs!$Q$8+L14*0.433 -> 1881.6688 | N14: =A14 -> 97099.92 | O14: =B14 -> 807.3161 | P14: =IF(O14="","",Inputs!$C$5-O14) -> 17.8684 | Q14: =IF(N14="","",TS!J14) -> 2000 | R14: =IF(N14="","",TS!K14) -> 1825 | S14: =Inputs!$H$5+TS!P14*0.4333 -> 1882.7081 | T14: =Inputs!$G$5+TS!P14*0.4333 -> 1897.7081 | U14: =T14/(140000*C14/42) -> 0.94885405 | V14: =O14-MAX(O14:O177) -> -5.3121 | W14: =-(V14)*0.433 -> 2.3001393 | X14: =((PI()*((42-2*'Gen Calcs'!$E$13)^2)/4)/144)*(A57-#REF!)*(W14+14.7)/14.7 -> #REF! | Y14: =X14/1000 -> #REF! | Z14: =IF(Y14>Z13,Y14,Z13) -> #REF! | AA14: =MAX(B$2:B14)-B14 -> 17.8684 | AB14: =AA14*0.433 -> 7.7370172 | AC14: =((MAX(O$2:O$1348)-O14)-(MAX(O$2:O$1348)-O14))*0.433+AD14 -> 95.890091 | AD14: =(AD$2*AF$1391)/AG14 -> 95.890091 | AE14: =PI()*(((42-2*C14)/12)^2/4)*D14 -> 907.92028 | AF14: =SUM(AE$2:AE14) -> 10895.043 | AG14: =AF$1391-AF14 -> 1162834.9
A15: 97199.92 | B15: 812.6282 | C15: 0.6 | D15: =A15-A14 -> 100 | E15: =(PI()/4*(42/12-(2*C57/12))^2)*(D15)*7.48 -> 6791.2437 | F15: =SUM(E$2:E15) -> 88111.532 | G15: =IF(C15=0.72,12,IF(C15=1,11,IF(C15=0.825,10,IF(C15=0.6,1,IF(C15=0.864,2,IF(C15=0.888,3)))))) -> 1 | H15: 1 | I15: =C15 -> 0.6 | J15: =VLOOKUP(G15,Inputs!$L$3:$P$15,5,FALSE) -> 2000 | K15: =IF(H15=1,1825,IF(H15=2,1825,2220)) -> 1825 | L15: =Inputs!$P$8-B15 -> 125.5628 | M15: =Inputs!$Q$8+L15*0.433 -> 1879.3687 | N15: =A15 -> 97199.92 | O15: =B15 -> 812.6282 | P15: =IF(O15="","",Inputs!$C$5-O15) -> 12.5563 | Q15: =IF(N15="","",TS!J15) -> 2000 | R15: =IF(N15="","",TS!K15) -> 1825 | S15: =Inputs!$H$5+TS!P15*0.4333 -> 1880.4064 | T15: =Inputs!$G$5+TS!P15*0.4333 -> 1895.4064 | U15: =T15/(140000*C15/42) -> 0.94770318 | V15: =O15-MAX(O15:O177) -> 0 | W15: =-(V15)*0.433 -> 0 | X15: =((PI()*((42-2*'Gen Calcs'!$E$13)^2)/4)/144)*(A58-#REF!)*(W15+14.7)/14.7 -> #REF! | Y15: =X15/1000 -> #REF! | Z15: =IF(Y15>Z14,Y15,Z14) -> #REF! | AA15: =MAX(B$2:B15)-B15 -> 12.5563 | AB15: =AA15*0.433 -> 5.4368779 | AC15: =((MAX(O$2:O$1348)-O15)-(MAX(O$2:O$1348)-O15))*0.433+AD15 -> 95.965019 | AD15: =(AD$2*AF$1391)/AG15 -> 95.965019 | AE15: =PI()*(((42-2*C15)/12)^2/4)*D15 -> 907.92028 | AF15: =SUM(AE$2:AE15) -> 11802.964 | AG15: =AF$1391-AF15 -> 1161926.9
A16: 97299.92 | B16: 811.2065 | C16: 0.6 | D16: =A16-A15 -> 100 | E16: =(PI()/4*(42/12-(2*C58/12))^2)*(D16)*7.48 -> 6791.2437 | F16: =SUM(E$2:E16) -> 94902.775 | G16: =IF(C16=0.72,12,IF(C16=1,11,IF(C16=0.825,10,IF(C16=0.6,1,IF(C16=0.864,2,IF(C16=0.888,3)))))) -> 1 | H16: 1 | I16: =C16 -> 0.6 | J16: =VLOOKUP(G16,Inputs!$L$3:$P$15,5,FALSE) -> 2000 | K16: =IF(H16=1,1825,IF(H16=2,1825,2220)) -> 1825 | L16: =Inputs!$P$8-B16 -> 126.9845 | M16: =Inputs!$Q$8+L16*0.433 -> 1879.9843 | N16: =A16 -> 97299.92 | O16: =B16 -> 811.2065 | P16: =IF(O16="","",Inputs!$C$5-O16) -> 13.978 | Q16: =IF(N16="","",TS!J16) -> 2000 | R16: =IF(N16="","",TS!K16) -> 1825 | S16: =Inputs!$H$5+TS!P16*0.4333 -> 1881.0224 | T16: =Inputs!$G$5+TS!P16*0.4333 -> 1896.0224 | U16: =T16/(140000*C16/42) -> 0.94801119 | V16: =O16-MAX(O16:O177) -> 0 | W16: =-(V16)*0.433 -> 0 | X16: =((PI()*((42-2*'Gen Calcs'!$E$13)^2)/4)/144)*(A59-#REF!)*(W16+14.7)/14.7 -> #REF! | Y16: =X16/1000 -> #REF! | Z16: =IF(Y16>Z15,Y16,Z15) -> #REF! | AA16: =MAX(B$2:B16)-B16 -> 13.978 | AB16: =AA16*0.433 -> 6.052474 | AC16: =((MAX(O$2:O$1348)-O16)-(MAX(O$2:O$1348)-O16))*0.433+AD16 -> 96.040064 | AD16: =(AD$2*AF$1391)/AG16 -> 96.040064 | AE16: =PI()*(((42-2*C16)/12)^2/4)*D16 -> 907.92028 | AF16: =SUM(AE$2:AE16) -> 12710.884 | AG16: =AF$1391-AF16 -> 1161019
A17: 97399.92 | B17: 808.8225 | C17: 0.6 | D17: =A17-A16 -> 100 | E17: =(PI()/4*(42/12-(2*C59/12))^2)*(D17)*7.48 -> 6791.2437 | F17: =SUM(E$2:E17) -> 101694.02 | G17: =IF(C17=0.72,12,IF(C17=1,11,IF(C17=0.825,10,IF(C17=0.6,1,IF(C17=0.864,2,IF(C17=0.888,3)))))) -> 1 | H17: 1 | I17: =C17 -> 0.6 | J17: =VLOOKUP(G17,Inputs!$L$3:$P$15,5,FALSE) -> 2000 | K17: =IF(H17=1,1825,IF(H17=2,1825,2220)) -> 1825 | L17: =Inputs!$P$8-B17 -> 129.3685 | M17: =Inputs!$Q$8+L17*0.433 -> 1881.0166 | N17: =A17 -> 97399.92 | O17: =B17 -> 808.8225 | P17: =IF(O17="","",Inputs!$C$5-O17) -> 16.362 | Q17: =IF(N17="","",TS!J17) -> 2000 | R17: =IF(N17="","",TS!K17) -> 1825 | S17: =Inputs!$H$5+TS!P17*0.4333 -> 1882.0554 | T17: =Inputs!$G$5+TS!P17*0.4333 -> 1897.0554 | U17: =T17/(140000*C17/42) -> 0.94852769 | V17: =O17-MAX(O17:O177) -> 0 | W17: =-(V17)*0.433 -> 0 | X17: =((PI()*((42-2*'Gen Calcs'!$E$13)^2)/4)/144)*(A60-#REF!)*(W17+14.7)/14.7 -> #REF! | Y17: =X17/1000 -> #REF! | Z17: =IF(Y17>Z16,Y17,Z16) -> #REF! | AA17: =MAX(B$2:B17)-B17 -> 16.362 | AB17: =AA17*0.433 -> 7.084746 | AC17: =((MAX(O$2:O$1348)-O17)-(MAX(O$2:O$1348)-O17))*0.433+AD17 -> 96.115226 | AD17: =(AD$2*AF$1391)/AG17 -> 96.115226 | AE17: =PI()*(((42-2*C17)/12)^2/4)*D17 -> 907.92028 | AF17: =SUM(AE$2:AE17) -> 13618.804 | AG17: =AF$1391-AF17 -> 1160111.1
A18: 97499.92 | B18: 806.5878 | C18: 0.6 | D18: =A18-A17 -> 100 | E18: =(PI()/4*(42/12-(2*C60/12))^2)*(D18)*7.48 -> 6791.2437 | F18: =SUM(E$2:E18) -> 108485.26 | G18: =IF(C18=0.72,12,IF(C18=1,11,IF(C18=0.825,10,IF(C18=0.6,1,IF(C18=0.864,2,IF(C18=0.888,3)))))) -> 1 | H18: 1 | I18: =C18 -> 0.6 | J18: =VLOOKUP(G18,Inputs!$L$3:$P$15,5,FALSE) -> 2000 | K18: =IF(H18=1,1825,IF(H18=2,1825,2220)) -> 1825 | L18: =Inputs!$P$8-B18 -> 131.6032 | M18: =Inputs!$Q$8+L18*0.433 -> 1881.9842 | N18: =A18 -> 97499.92 | O18: =B18 -> 806.5878 | P18: =IF(O18="","",Inputs!$C$5-O18) -> 18.5967 | Q18: =IF(N18="","",TS!J18) -> 2000 | R18: =IF(N18="","",TS!K18) -> 1825 | S18: =Inputs!$H$5+TS!P18*0.4333 -> 1883.0237 | T18: =Inputs!$G$5+TS!P18*0.4333 -> 1898.0237 | U18: =T18/(140000*C18/42) -> 0.94901183 | V18: =O18-MAX(O18:O177) -> 0 | W18: =-(V18)*0.433 -> 0 | X18: =((PI()*((42-2*'Gen Calcs'!$E$13)^2)/4)/144)*(A61-#REF!)*(W18+14.7)/14.7 -> #REF! | Y18: =X18/1000 -> #REF! | Z18: =IF(Y18>Z17,Y18,Z17) -> #REF! | AA18: =MAX(B$2:B18)-B18 -> 18.5967 | AB18: =AA18*0.433 -> 8.0523711 | AC18: =((MAX(O$2:O$1348)-O18)-(MAX(O$2:O$1348)-O18))*0.433+AD18 -> 96.190506 | AD18: =(AD$2*AF$1391)/AG18 -> 96.190506 | AE18: =PI()*(((42-2*C18)/12)^2/4)*D18 -> 907.92028 | AF18: =SUM(AE$2:AE18) -> 14526.724 | AG18: =AF$1391-AF18 -> 1159203.2
A19: 97599.92 | B19: 804.4325 | C19: 0.6 | D19: =A19-A18 -> 100 | E19: =(PI()/4*(42/12-(2*C61/12))^2)*(D19)*7.48 -> 6791.2437 | F19: =SUM(E$2:E19) -> 115276.51 | G19: =IF(C19=0.72,12,IF(C19=1,11,IF(C19=0.825,10,IF(C19=0.6,1,IF(C19=0.864,2,IF(C19=0.888,3)))))) -> 1 | H19: 1 | I19: =C19 -> 0.6 | J19: =VLOOKUP(G19,Inputs!$L$3:$P$15,5,FALSE) -> 2000 | K19: =IF(H19=1,1825,IF(H19=2,1825,2220)) -> 1825 | L19: =Inputs!$P$8-B19 -> 133.7585 | M19: =Inputs!$Q$8+L19*0.433 -> 1882.9174 | N19: =A19 -> 97599.92 | O19: =B19 -> 804.4325 | P19: =IF(O19="","",Inputs!$C$5-O19) -> 20.752 | Q19: =IF(N19="","",TS!J19) -> 2000 | R19: =IF(N19="","",TS!K19) -> 1825 | S19: =Inputs!$H$5+TS!P19*0.4333 -> 1883.9576 | T19: =Inputs!$G$5+TS!P19*0.4333 -> 1898.9576 | U19: =T19/(140000*C19/42) -> 0.94947878 | V19: =O19-MAX(O19:O177) -> 0 | W19: =-(V19)*0.433 -> 0 | X19: =((PI()*((42-2*'Gen Calcs'!$E$13)^2)/4)/144)*(A62-#REF!)*(W19+14.7)/14.7 -> #REF! | Y19: =X19/1000 -> #REF! | Z19: =IF(Y19>Z18,Y19,Z18) -> #REF! | AA19: =MAX(B$2:B19)-B19 -> 20.752 | AB19: =AA19*0.433 -> 8.985616 | AC19: =((MAX(O$2:O$1348)-O19)-(MAX(O$2:O$1348)-O19))*0.433+AD19 -> 96.265905 | AD19: =(AD$2*AF$1391)/AG19 -> 96.265905 | AE19: =PI()*(((42-2*C19)/12)^2/4)*D19 -> 907.92028 | AF19: =SUM(AE$2:AE19) -> 15434.645 | AG19: =AF$1391-AF19 -> 1158295.3
A20: 97699.92 | B20: 801.5164 | C20: 0.6 | D20: =A20-A19 -> 100 | E20: =(PI()/4*(42/12-(2*C62/12))^2)*(D20)*7.48 -> 6791.2437 | F20: =SUM(E$2:E20) -> 122067.75 | G20: =IF(C20=0.72,12,IF(C20=1,11,IF(C20=0.825,10,IF(C20=0.6,1,IF(C20=0.864,2,IF(C20=0.888,3)))))) -> 1 | H20: 1 | I20: =C20 -> 0.6 | J20: =VLOOKUP(G20,Inputs!$L$3:$P$15,5,FALSE) -> 2000 | K20: =IF(H20=1,1825,IF(H20=2,1825,2220)) -> 1825 | L20: =Inputs!$P$8-B20 -> 136.6746 | M20: =Inputs!$Q$8+L20*0.433 -> 1884.1801 | N20: =A20 -> 97699.92 | O20: =B20 -> 801.5164 | P20: =IF(O20="","",Inputs!$C$5-O20) -> 23.6681 | Q20: =IF(N20="","",TS!J20) -> 2000 | R20: =IF(N20="","",TS!K20) -> 1825 | S20: =Inputs!$H$5+TS!P20*0.4333 -> 1885.2211 | T20: =Inputs!$G$5+TS!P20*0.4333 -> 1900.2211 | U20: =T20/(140000*C20/42) -> 0.95011055 | V20: =O20-MAX(O20:O177) -> 0 | W20: =-(V20)*0.433 -> 0 | X20: =((PI()*((42-2*'Gen Calcs'!$E$13)^2)/4)/144)*(A63-#REF!)*(W20+14.7)/14.7 -> #REF! | Y20: =X20/1000 -> #REF! | Z20: =IF(Y20>Z19,Y20,Z19) -> #REF! | AA20: =MAX(B$2:B20)-B20 -> 23.6681 | AB20: =AA20*0.433 -> 10.248287 | AC20: =((MAX(O$2:O$1348)-O20)-(MAX(O$2:O$1348)-O20))*0.433+AD20 -> 96.341421 | AD20: =(AD$2*AF$1391)/AG20 -> 96.341421 | AE20: =PI()*(((42-2*C20)/12)^2/4)*D20 -> 907.92028 | AF20: =SUM(AE$2:AE20) -> 16342.565 | AG20: =AF$1391-AF20 -> 1157387.3
A21: 97799.92 | B21: 798.9809 | C21: 0.6 | D21: =A21-A20 -> 100 | E21: =(PI()/4*(42/12-(2*C63/12))^2)*(D21)*7.48 -> 6791.2437 | F21: =SUM(E$2:E21) -> 128858.99 | G21: =IF(C21=0.72,12,IF(C21=1,11,IF(C21=0.825,10,IF(C21=0.6,1,IF(C21=0.864,2,IF(C21=0.888,3)))))) -> 1 | H21: 1 | I21: =C21 -> 0.6 | J21: =VLOOKUP(G21,Inputs!$L$3:$P$15,5,FALSE) -> 2000 | K21: =IF(H21=1,1825,IF(H21=2,1825,2220)) -> 1825 | L21: =Inputs!$P$8-B21 -> 139.2101 | M21: =Inputs!$Q$8+L21*0.433 -> 1885.278 | N21: =A21 -> 97799.92 | O21: =B21 -> 798.9809 | P21: =IF(O21="","",Inputs!$C$5-O21) -> 26.2036 | Q21: =IF(N21="","",TS!J21) -> 2000 | R21: =IF(N21="","",TS!K21) -> 1825 | S21: =Inputs!$H$5+TS!P21*0.4333 -> 1886.3197 | T21: =Inputs!$G$5+TS!P21*0.4333 -> 1901.3197 | U21: =T21/(140000*C21/42) -> 0.95065987 | V21: =O21-MAX(O21:O177) -> 0 | W21: =-(V21)*0.433 -> 0 | X21: =((PI()*((42-2*'Gen Calcs'!$E$13)^2)/4)/144)*(A64-#REF!)*(W21+14.7)/14.7 -> #REF! | Y21: =X21/1000 -> #REF! | Z21: =IF(Y21>Z20,Y21,Z20) -> #REF! | AA21: =MAX(B$2:B21)-B21 -> 26.2036 | AB21: =AA21*0.433 -> 11.346159 | AC21: =((MAX(O$2:O$1348)-O21)-(MAX(O$2:O$1348)-O21))*0.433+AD21 -> 96.417056 | AD21: =(AD$2*AF$1391)/AG21 -> 96.417056 | AE21: =PI()*(((42-2*C21)/12)^2/4)*D21 -> 907.92028 | AF21: =SUM(AE$2:AE21) -> 17250.485 | AG21: =AF$1391-AF21 -> 1156479.4
A22: 97899.92 | B22: 790.8558 | C22: 0.6 | D22: =A22-A21 -> 100 | E22: =(PI()/4*(42/12-(2*C64/12))^2)*(D22)*7.48 -> 6791.2437 | F22: =SUM(E$2:E22) -> 135650.24 | G22: =IF(C22=0.72,12,IF(C22=1,11,IF(C22=0.825,10,IF(C22=0.6,1,IF(C22=0.864,2,IF(C22=0.888,3)))))) -> 1 | H22: 1 | I22: =C22 -> 0.6 | J22: =VLOOKUP(G22,Inputs!$L$3:$P$15,5,FALSE) -> 2000 | K22: =IF(H22=1,1825,IF(H22=2,1825,2220)) -> 1825 | L22: =Inputs!$P$8-B22 -> 147.3352 | M22: =Inputs!$Q$8+L22*0.433 -> 1888.7961 | N22: =A22 -> 97899.92 | O22: =B22 -> 790.8558 | P22: =IF(O22="","",Inputs!$C$5-O22) -> 34.3287 | Q22: =IF(N22="","",TS!J22) -> 2000 | R22: =IF(N22="","",TS!K22) -> 1825 | S22: =Inputs!$H$5+TS!P22*0.4333 -> 1889.8403 | T22: =Inputs!$G$5+TS!P22*0.4333 -> 1904.8403 | U22: =T22/(140000*C22/42) -> 0.95242017 | V22: =O22-MAX(O22:O177) -> 0 | W22: =-(V22)*0.433 -> 0 | X22: =((PI()*((42-2*'Gen Calcs'!$E$13)^2)/4)/144)*(A65-#REF!)*(W22+14.7)/14.7 -> #REF! | Y22: =X22/1000 -> #REF! | Z22: =IF(Y22>Z21,Y22,Z21) -> #REF! | AA22: =MAX(B$2:B22)-B22 -> 34.3287 | AB22: =AA22*0.433 -> 14.864327 | AC22: =((MAX(O$2:O$1348)-O22)-(MAX(O$2:O$1348)-O22))*0.433+AD22 -> 96.49281 | AD22: =(AD$2*AF$1391)/AG22 -> 96.49281 | AE22: =PI()*(((42-2*C22)/12)^2/4)*D22 -> 907.92028 | AF22: =SUM(AE$2:AE22) -> 18158.406 | AG22: =AF$1391-AF22 -> 1155571.5
A23: 97999.92 | B23: 777.3192 | C23: 0.6 | D23: =A23-A22 -> 100 | E23: =(PI()/4*(42/12-(2*C65/12))^2)*(D23)*7.48 -> 6791.2437 | F23: =SUM(E$2:E23) -> 142441.48 | G23: =IF(C23=0.72,12,IF(C23=1,11,IF(C23=0.825,10,IF(C23=0.6,1,IF(C23=0.864,2,IF(C23=0.888,3)))))) -> 1 | H23: 1 | I23: =C23 -> 0.6 | J23: =VLOOKUP(G23,Inputs!$L$3:$P$15,5,FALSE) -> 2000 | K23: =IF(H23=1,1825,IF(H23=2,1825,2220)) -> 1825 | L23: =Inputs!$P$8-B23 -> 160.8718 | M23: =Inputs!$Q$8+L23*0.433 -> 1894.6575 | N23: =A23 -> 97999.92 | O23: =B23 -> 777.3192 | P23: =IF(O23="","",Inputs!$C$5-O23) -> 47.8653 | Q23: =IF(N23="","",TS!J23) -> 2000 | R23: =IF(N23="","",TS!K23) -> 1825 | S23: =Inputs!$H$5+TS!P23*0.4333 -> 1895.7058 | T23: =Inputs!$G$5+TS!P23*0.4333 -> 1910.7058 | U23: =T23/(140000*C23/42) -> 0.95535288 | V23: =O23-MAX(O23:O177) -> 0 | W23: =-(V23)*0.433 -> 0 | X23: =((PI()*((42-2*'Gen Calcs'!$E$13)^2)/4)/144)*(A66-#REF!)*(W23+14.7)/14.7 -> #REF! | Y23: =X23/1000 -> #REF! | Z23: =IF(Y23>Z22,Y23,Z22) -> #REF! | AA23: =MAX(B$2:B23)-B23 -> 47.8653 | AB23: =AA23*0.433 -> 20.725675 | AC23: =((MAX(O$2:O$1348)-O23)-(MAX(O$2:O$1348)-O23))*0.433+AD23 -> 96.568683 | AD23: =(AD$2*AF$1391)/AG23 -> 96.568683 | AE23: =PI()*(((42-2*C23)/12)^2/4)*D23 -> 907.92028 | AF23: =SUM(AE$2:AE23) -> 19066.326 | AG23: =AF$1391-AF23 -> 1154663.6
A24: 98099.92 | B24: 752.5068 | C24: 0.6 | D24: =A24-A23 -> 100 | E24: =(PI()/4*(42/12-(2*C66/12))^2)*(D24)*7.48 -> 6616.6077 | F24: =SUM(E$2:E24) -> 149058.09 | G24: =IF(C24=0.72,12,IF(C24=1,11,IF(C24=0.825,10,IF(C24=0.6,1,IF(C24=0.864,2,IF(C24=0.888,3)))))) -> 1 | H24: 1 | I24: =C24 -> 0.6 | J24: =VLOOKUP(G24,Inputs!$L$3:$P$15,5,FALSE) -> 2000 | K24: =IF(H24=1,1825,IF(H24=2,1825,2220)) -> 1825 | L24: =Inputs!$P$8-B24 -> 185.6842 | M24: =Inputs!$Q$8+L24*0.433 -> 1905.4013 | N24: =A24 -> 98099.92 | O24: =B24 -> 752.5068 | P24: =IF(O24="","",Inputs!$C$5-O24) -> 72.6777 | Q24: =IF(N24="","",TS!J24) -> 2000 | R24: =IF(N24="","",TS!K24) -> 1825 | S24: =Inputs!$H$5+TS!P24*0.4333 -> 1906.457 | T24: =Inputs!$G$5+TS!P24*0.4333 -> 1921.457 | U24: =T24/(140000*C24/42) -> 0.96072848 | V24: =O24-MAX(O24:O177) -> 0 | W24: =-(V24)*0.433 -> 0 | X24: =((PI()*((42-2*'Gen Calcs'!$E$13)^2)/4)/144)*(A67-#REF!)*(W24+14.7)/14.7 -> #REF! | Y24: =X24/1000 -> #REF! | Z24: =IF(Y24>Z23,Y24,Z23) -> #REF! | AA24: =MAX(B$2:B24)-B24 -> 72.6777 | AB24: =AA24*0.433 -> 31.469444 | AC24: =((MAX(O$2:O$1348)-O24)-(MAX(O$2:O$1348)-O24))*0.433+AD24 -> 96.644675 | AD24: =(AD$2*AF$1391)/AG24 -> 96.644675 | AE24: =PI()*(((42-2*C24)/12)^2/4)*D24 -> 907.92028 | AF24: =SUM(AE$2:AE24) -> 19974.246 | AG24: =AF$1391-AF24 -> 1153755.7
A25: 98199.92 | B25: 743.8488 | C25: 0.6 | D25: =A25-A24 -> 100 | E25: =(PI()/4*(42/12-(2*C67/12))^2)*(D25)*7.48 -> 6791.2437 | F25: =SUM(E$2:E25) -> 155849.33 | G25: =IF(C25=0.72,12,IF(C25=1,11,IF(C25=0.825,10,IF(C25=0.6,1,IF(C25=0.864,2,IF(C25=0.888,3)))))) -> 1 | H25: 1 | I25: =C25 -> 0.6 | J25: =VLOOKUP(G25,Inputs!$L$3:$P$15,5,FALSE) -> 2000 | K25: =IF(H25=1,1825,IF(H25=2,1825,2220)) -> 1825 | L25: =Inputs!$P$8-B25 -> 194.3422 | M25: =Inputs!$Q$8+L25*0.433 -> 1909.1502 | N25: =A25 -> 98199.92 | O25: =B25 -> 743.8488 | P25: =IF(O25="","",Inputs!$C$5-O25) -> 81.3357 | Q25: =IF(N25="","",TS!J25) -> 2000 | R25: =IF(N25="","",TS!K25) -> 1825 | S25: =Inputs!$H$5+TS!P25*0.4333 -> 1910.2085 | T25: =Inputs!$G$5+TS!P25*0.4333 -> 1925.2085 | U25: =T25/(140000*C25/42) -> 0.96260424 | V25: =O25-MAX(O25:O177) -> 0 | W25: =-(V25)*0.433 -> 0 | X25: =((PI()*((42-2*'Gen Calcs'!$E$13)^2)/4)/144)*(A68-#REF!)*(W25+14.7)/14.7 -> #REF! | Y25: =X25/1000 -> #REF! | Z25: =IF(Y25>Z24,Y25,Z24) -> #REF! | AA25: =MAX(B$2:B25)-B25 -> 81.3357 | AB25: =AA25*0.433 -> 35.218358 | AC25: =((MAX(O$2:O$1348)-O25)-(MAX(O$2:O$1348)-O25))*0.433+AD25 -> 96.720787 | AD25: =(AD$2*AF$1391)/AG25 -> 96.720787 | AE25: =PI()*(((42-2*C25)/12)^2/4)*D25 -> 907.92028 | AF25: =SUM(AE$2:AE25) -> 20882.166 | AG25: =AF$1391-AF25 -> 1152847.7
A26: 98299.92 | B26: 733.6733 | C26: 0.6 | D26: =A26-A25 -> 100 | E26: =(PI()/4*(42/12-(2*C68/12))^2)*(D26)*7.48 -> 6791.2437 | F26: =SUM(E$2:E26) -> 162640.58 | G26: =IF(C26=0.72,12,IF(C26=1,11,IF(C26=0.825,10,IF(C26=0.6,1,IF(C26=0.864,2,IF(C26=0.888,3)))))) -> 1 | H26: 1 | I26: =C26 -> 0.6 | J26: =VLOOKUP(G26,Inputs!$L$3:$P$15,5,FALSE) -> 2000 | K26: =IF(H26=1,1825,IF(H26=2,1825,2220)) -> 1825 | L26: =Inputs!$P$8-B26 -> 204.5177 | M26: =Inputs!$Q$8+L26*0.433 -> 1913.5562 | N26: =A26 -> 98299.92 | O26: =B26 -> 733.6733 | P26: =IF(O26="","",Inputs!$C$5-O26) -> 91.5112 | Q26: =IF(N26="","",TS!J26) -> 2000 | R26: =IF(N26="","",TS!K26) -> 1825 | S26: =Inputs!$H$5+TS!P26*0.4333 -> 1914.6175 | T26: =Inputs!$G$5+TS!P26*0.4333 -> 1929.6175 | U26: =T26/(140000*C26/42) -> 0.96480876 | V26: =O26-MAX(O26:O177) -> 0 | W26: =-(V26)*0.433 -> 0 | X26: =((PI()*((42-2*'Gen Calcs'!$E$13)^2)/4)/144)*(A69-#REF!)*(W26+14.7)/14.7 -> #REF! | Y26: =X26/1000 -> #REF! | Z26: =IF(Y26>Z25,Y26,Z25) -> #REF! | AA26: =MAX(B$2:B26)-B26 -> 91.5112 | AB26: =AA26*0.433 -> 39.62435 | AC26: =((MAX(O$2:O$1348)-O26)-(MAX(O$2:O$1348)-O26))*0.433+AD26 -> 96.797019 | AD26: =(AD$2*AF$1391)/AG26 -> 96.797019 | AE26: =PI()*(((42-2*C26)/12)^2/4)*D26 -> 907.92028 | AF26: =SUM(AE$2:AE26) -> 21790.087 | AG26: =AF$1391-AF26 -> 1151939.8
A27: 98399.92 | B27: 713.5777 | C27: 0.6 | D27: =A27-A26 -> 100 | E27: =(PI()/4*(42/12-(2*C69/12))^2)*(D27)*7.48 -> 6791.2437 | F27: =SUM(E$2:E27) -> 169431.82 | G27: =IF(C27=0.72,12,IF(C27=1,11,IF(C27=0.825,10,IF(C27=0.6,1,IF(C27=0.864,2,IF(C27=0.888,3)))))) -> 1 | H27: 1 | I27: =C27 -> 0.6 | J27: =VLOOKUP(G27,Inputs!$L$3:$P$15,5,FALSE) -> 2000 | K27: =IF(H27=1,1825,IF(H27=2,1825,2220)) -> 1825 | L27: =Inputs!$P$8-B27 -> 224.6133 | M27: =Inputs!$Q$8+L27*0.433 -> 1922.2576 | N27: =A27 -> 98399.92 | O27: =B27 -> 713.5777 | P27: =IF(O27="","",Inputs!$C$5-O27) -> 111.6068 | Q27: =IF(N27="","",TS!J27) -> 2000 | R27: =IF(N27="","",TS!K27) -> 1825 | S27: =Inputs!$H$5+TS!P27*0.4333 -> 1923.3249 | T27: =Inputs!$G$5+TS!P27*0.4333 -> 1938.3249 | U27: =T27/(140000*C27/42) -> 0.96916247 | V27: =O27-MAX(O27:O177) -> 0 | W27: =-(V27)*0.433 -> 0 | X27: =((PI()*((42-2*'Gen Calcs'!$E$13)^2)/4)/144)*(A70-#REF!)*(W27+14.7)/14.7 -> #REF! | Y27: =X27/1000 -> #REF! | Z27: =IF(Y27>Z26,Y27,Z26) -> #REF! | AA27: =MAX(B$2:B27)-B27 -> 111.6068 | AB27: =AA27*0.433 -> 48.325744 | AC27: =((MAX(O$2:O$1348)-O27)-(MAX(O$2:O$1348)-O27))*0.433+AD27 -> 96.873372 | AD27: =(AD$2*AF$1391)/AG27 -> 96.873372 | AE27: =PI()*(((42-2*C27)/12)^2/4)*D27 -> 907.92028 | AF27: =SUM(AE$2:AE27) -> 22698.007 | AG27: =AF$1391-AF27 -> 1151031.9
A28: 98499.92 | B28: 701.03 | C28: 0.6 | D28: =A28-A27 -> 100 | E28: =(PI()/4*(42/12-(2*C70/12))^2)*(D28)*7.48 -> 6791.2437 | F28: =SUM(E$2:E28) -> 176223.06 | G28: =IF(C28=0.72,12,IF(C28=1,11,IF(C28=0.825,10,IF(C28=0.6,1,IF(C28=0.864,2,IF(C28=0.888,3)))))) -> 1 | H28: 1 | I28: =C28 -> 0.6 | J28: =VLOOKUP(G28,Inputs!$L$3:$P$15,5,FALSE) -> 2000 | K28: =IF(H28=1,1825,IF(H28=2,1825,2220)) -> 1825 | L28: =Inputs!$P$8-B28 -> 237.161 | M28: =Inputs!$Q$8+L28*0.433 -> 1927.6907 | N28: =A28 -> 98499.92 | O28: =B28 -> 701.03 | P28: =IF(O28="","",Inputs!$C$5-O28) -> 124.1545 | Q28: =IF(N28="","",TS!J28) -> 2000 | R28: =IF(N28="","",TS!K28) -> 1825 | S28: =Inputs!$H$5+TS!P28*0.4333 -> 1928.7619 | T28: =Inputs!$G$5+TS!P28*0.4333 -> 1943.7619 | U28: =T28/(140000*C28/42) -> 0.97188093 | V28: =O28-MAX(O28:O177) -> 0 | W28: =-(V28)*0.433 -> 0 | X28: =((PI()*((42-2*'Gen Calcs'!$E$13)^2)/4)/144)*(A71-#REF!)*(W28+14.7)/14.7 -> #REF! | Y28: =X28/1000 -> #REF! | Z28: =IF(Y28>Z27,Y28,Z27) -> #REF! | AA28: =MAX(B$2:B28)-B28 -> 124.1545 | AB28: =AA28*0.433 -> 53.758898 | AC28: =((MAX(O$2:O$1348)-O28)-(MAX(O$2:O$1348)-O28))*0.433+AD28 -> 96.949845 | AD28: =(AD$2*AF$1391)/AG28 -> 96.949845 | AE28: =PI()*(((42-2*C28)/12)^2/4)*D28 -> 907.92028 | AF28: =SUM(AE$2:AE28) -> 23605.927 | AG28: =AF$1391-AF28 -> 1150124
A29: 98599.92 | B29: 693.1732 | C29: 0.6 | D29: =A29-A28 -> 100 | E29: =(PI()/4*(42/12-(2*C71/12))^2)*(D29)*7.48 -> 6791.2437 | F29: =SUM(E$2:E29) -> 183014.31 | G29: =IF(C29=0.72,12,IF(C29=1,11,IF(C29=0.825,10,IF(C29=0.6,1,IF(C29=0.864,2,IF(C29=0.888,3)))))) -> 1 | H29: 1 | I29: =C29 -> 0.6 | J29: =VLOOKUP(G29,Inputs!$L$3:$P$15,5,FALSE) -> 2000 | K29: =IF(H29=1,1825,IF(H29=2,1825,2220)) -> 1825 | L29: =Inputs!$P$8-B29 -> 245.0178 | M29: =Inputs!$Q$8+L29*0.433 -> 1931.0927 | N29: =A29 -> 98599.92 | O29: =B29 -> 693.1732 | P29: =IF(O29="","",Inputs!$C$5-O29) -> 132.0113 | Q29: =IF(N29="","",TS!J29) -> 2000 | R29: =IF(N29="","",TS!K29) -> 1825 | S29: =Inputs!$H$5+TS!P29*0.4333 -> 1932.1662 | T29: =Inputs!$G$5+TS!P29*0.4333 -> 1947.1662 | U29: =T29/(140000*C29/42) -> 0.97358311 | V29: =O29-MAX(O29:O177) -> -1.0227 | W29: =-(V29)*0.433 -> 0.4428291 | X29: =((PI()*((42-2*'Gen Calcs'!$E$13)^2)/4)/144)*(A72-#REF!)*(W29+14.7)/14.7 -> #REF! | Y29: =X29/1000 -> #REF! | Z29: =IF(Y29>Z28,Y29,Z28) -> #REF! | AA29: =MAX(B$2:B29)-B29 -> 132.0113 | AB29: =AA29*0.433 -> 57.160893 | AC29: =((MAX(O$2:O$1348)-O29)-(MAX(O$2:O$1348)-O29))*0.433+AD29 -> 97.026438 | AD29: =(AD$2*AF$1391)/AG29 -> 97.026438 | AE29: =PI()*(((42-2*C29)/12)^2/4)*D29 -> 907.92028 | AF29: =SUM(AE$2:AE29) -> 24513.847 | AG29: =AF$1391-AF29 -> 1149216.1
A30: 98699.92 | B30: 685.2826 | C30: 0.6 | D30: =A30-A29 -> 100 | E30: =(PI()/4*(42/12-(2*C72/12))^2)*(D30)*7.48 -> 6791.2437 | F30: =SUM(E$2:E30) -> 189805.55 | G30: =IF(C30=0.72,12,IF(C30=1,11,IF(C30=0.825,10,IF(C30=0.6,1,IF(C30=0.864,2,IF(C30=0.888,3)))))) -> 1 | H30: 1 | I30: =C30 -> 0.6 | J30: =VLOOKUP(G30,Inputs!$L$3:$P$15,5,FALSE) -> 2000 | K30: =IF(H30=1,1825,IF(H30=2,1825,2220)) -> 1825 | L30: =Inputs!$P$8-B30 -> 252.9084 | M30: =Inputs!$Q$8+L30*0.433 -> 1934.5093 | N30: =A30 -> 98699.92 | O30: =B30 -> 685.2826 | P30: =IF(O30="","",Inputs!$C$5-O30) -> 139.9019 | Q30: =IF(N30="","",TS!J30) -> 2000 | R30: =IF(N30="","",TS!K30) -> 1825 | S30: =Inputs!$H$5+TS!P30*0.4333 -> 1935.5852 | T30: =Inputs!$G$5+TS!P30*0.4333 -> 1950.5852 | U30: =T30/(140000*C30/42) -> 0.9752926 | V30: =O30-MAX(O30:O177) -> -8.9133 | W30: =-(V30)*0.433 -> 3.8594589 | X30: =((PI()*((42-2*'Gen Calcs'!$E$13)^2)/4)/144)*(A73-#REF!)*(W30+14.7)/14.7 -> #REF! | Y30: =X30/1000 -> #REF! | Z30: =IF(Y30>Z29,Y30,Z29) -> #REF! | AA30: =MAX(B$2:B30)-B30 -> 139.9019 | AB30: =AA30*0.433 -> 60.577523 | AC30: =((MAX(O$2:O$1348)-O30)-(MAX(O$2:O$1348)-O30))*0.433+AD30 -> 97.103153 | AD30: =(AD$2*AF$1391)/AG30 -> 97.103153 | AE30: =PI()*(((42-2*C30)/12)^2/4)*D30 -> 907.92028 | AF30: =SUM(AE$2:AE30) -> 25421.768 | AG30: =AF$1391-AF30 -> 1148308.1
A31: 98799.92 | B31: 682.066 | C31: 0.6 | D31: =A31-A30 -> 100 | E31: =(PI()/4*(42/12-(2*C73/12))^2)*(D31)*7.48 -> 6791.2437 | F31: =SUM(E$2:E31) -> 196596.79 | G31: =IF(C31=0.72,12,IF(C31=1,11,IF(C31=0.825,10,IF(C31=0.6,1,IF(C31=0.864,2,IF(C31=0.888,3)))))) -> 1 | H31: 1 | I31: =C31 -> 0.6 | J31: =VLOOKUP(G31,Inputs!$L$3:$P$15,5,FALSE) -> 2000 | K31: =IF(H31=1,1825,IF(H31=2,1825,2220)) -> 1825 | L31: =Inputs!$P$8-B31 -> 256.125 | M31: =Inputs!$Q$8+L31*0.433 -> 1935.9021 | N31: =A31 -> 98799.92 | O31: =B31 -> 682.066 | P31: =IF(O31="","",Inputs!$C$5-O31) -> 143.1185 | Q31: =IF(N31="","",TS!J31) -> 2000 | R31: =IF(N31="","",TS!K31) -> 1825 | S31: =Inputs!$H$5+TS!P31*0.4333 -> 1936.979 | T31: =Inputs!$G$5+TS!P31*0.4333 -> 1951.979 | U31: =T31/(140000*C31/42) -> 0.97598948 | V31: =O31-MAX(O31:O177) -> -12.1299 | W31: =-(V31)*0.433 -> 5.2522467 | X31: =((PI()*((42-2*'Gen Calcs'!$E$13)^2)/4)/144)*(A74-#REF!)*(W31+14.7)/14.7 -> #REF! | Y31: =X31/1000 -> #REF! | Z31: =IF(Y31>Z30,Y31,Z30) -> #REF! | AA31: =MAX(B$2:B31)-B31 -> 143.1185 | AB31: =AA31*0.433 -> 61.97031 | AC31: =((MAX(O$2:O$1348)-O31)-(MAX(O$2:O$1348)-O31))*0.433+AD31 -> 97.179989 | AD31: =(AD$2*AF$1391)/AG31 -> 97.179989 | AE31: =PI()*(((42-2*C31)/12)^2/4)*D31 -> 907.92028 | AF31: =SUM(AE$2:AE31) -> 26329.688 | AG31: =AF$1391-AF31 -> 1147400.2
A32: 98899.92 | B32: 675.8824 | C32: 0.6 | D32: =A32-A31 -> 100 | E32: =(PI()/4*(42/12-(2*C74/12))^2)*(D32)*7.48 -> 6791.2437 | F32: =SUM(E$2:E32) -> 203388.04 | G32: =IF(C32=0.72,12,IF(C32=1,11,IF(C32=0.825,10,IF(C32=0.6,1,IF(C32=0.864,2,IF(C32=0.888,3)))))) -> 1 | H32: 1 | I32: =C32 -> 0.6 | J32: =VLOOKUP(G32,Inputs!$L$3:$P$15,5,FALSE) -> 2000 | K32: =IF(H32=1,1825,IF(H32=2,1825,2220)) -> 1825 | L32: =Inputs!$P$8-B32 -> 262.3086 | M32: =Inputs!$Q$8+L32*0.433 -> 1938.5796 | N32: =A32 -> 98899.92 | O32: =B32 -> 675.8824 | P32: =IF(O32="","",Inputs!$C$5-O32) -> 149.3021 | Q32: =IF(N32="","",TS!J32) -> 2000 | R32: =IF(N32="","",TS!K32) -> 1825 | S32: =Inputs!$H$5+TS!P32*0.4333 -> 1939.6583 | T32: =Inputs!$G$5+TS!P32*0.4333 -> 1954.6583 | U32: =T32/(140000*C32/42) -> 0.97732916 | V32: =O32-MAX(O32:O177) -> -18.3135 | W32: =-(V32)*0.433 -> 7.9297455 | X32: =((PI()*((42-2*'Gen Calcs'!$E$13)^2)/4)/144)*(A75-#REF!)*(W32+14.7)/14.7 -> #REF! | Y32: =X32/1000 -> #REF! | Z32: =IF(Y32>Z31,Y32,Z31) -> #REF! | AA32: =MAX(B$2:B32)-B32 -> 149.3021 | AB32: =AA32*0.433 -> 64.647809 | AC32: =((MAX(O$2:O$1348)-O32)-(MAX(O$2:O$1348)-O32))*0.433+AD32 -> 97.256947 | AD32: =(AD$2*AF$1391)/AG32 -> 97.256947 | AE32: =PI()*(((42-2*C32)/12)^2/4)*D32 -> 907.92028 | AF32: =SUM(AE$2:AE32) -> 27237.608 | AG32: =AF$1391-AF32 -> 1146492.3
A33: 98999.92 | B33: 686.3181 | C33: 0.6 | D33: =A33-A32 -> 100 | E33: =(PI()/4*(42/12-(2*C75/12))^2)*(D33)*7.48 -> 6791.2437 | F33: =SUM(E$2:E33) -> 210179.28 | G33: =IF(C33=0.72,12,IF(C33=1,11,IF(C33=0.825,10,IF(C33=0.6,1,IF(C33=0.864,2,IF(C33=0.888,3)))))) -> 1 | H33: 1 | I33: =C33 -> 0.6 | J33: =VLOOKUP(G33,Inputs!$L$3:$P$15,5,FALSE) -> 2000 | K33: =IF(H33=1,1825,IF(H33=2,1825,2220)) -> 1825 | L33: =Inputs!$P$8-B33 -> 251.8729 | M33: =Inputs!$Q$8+L33*0.433 -> 1934.061 | N33: =A33 -> 98999.92 | O33: =B33 -> 686.3181 | P33: =IF(O33="","",Inputs!$C$5-O33) -> 138.8664 | Q33: =IF(N33="","",TS!J33) -> 2000 | R33: =IF(N33="","",TS!K33) -> 1825 | S33: =Inputs!$H$5+TS!P33*0.4333 -> 1935.1365 | T33: =Inputs!$G$5+TS!P33*0.4333 -> 1950.1365 | U33: =T33/(140000*C33/42) -> 0.97506826 | V33: =O33-MAX(O33:O177) -> -7.8778 | W33: =-(V33)*0.433 -> 3.4110874 | X33: =((PI()*((42-2*'Gen Calcs'!$E$13)^2)/4)/144)*(A76-#REF!)*(W33+14.7)/14.7 -> #REF! | Y33: =X33/1000 -> #REF! | Z33: =IF(Y33>Z32,Y33,Z32) -> #REF! | AA33: =MAX(B$2:B33)-B33 -> 138.8664 | AB33: =AA33*0.433 -> 60.129151 | AC33: =((MAX(O$2:O$1348)-O33)-(MAX(O$2:O$1348)-O33))*0.433+AD33 -> 97.334027 | AD33: =(AD$2*AF$1391)/AG33 -> 97.334027 | AE33: =PI()*(((42-2*C33)/12)^2/4)*D33 -> 907.92028 | AF33: =SUM(AE$2:AE33) -> 28145.529 | AG33: =AF$1391-AF33 -> 1145584.4
A34: 99099.92 | B34: 690.9545 | C34: 0.6 | D34: =A34-A33 -> 100 | E34: =(PI()/4*(42/12-(2*C76/12))^2)*(D34)*7.48 -> 6791.2437 | F34: =SUM(E$2:E34) -> 216970.53 | G34: =IF(C34=0.72,12,IF(C34=1,11,IF(C34=0.825,10,IF(C34=0.6,1,IF(C34=0.864,2,IF(C34=0.888,3)))))) -> 1 | H34: 1 | I34: =C34 -> 0.6 | J34: =VLOOKUP(G34,Inputs!$L$3:$P$15,5,FALSE) -> 2000 | K34: =IF(H34=1,1825,IF(H34=2,1825,2220)) -> 1825 | L34: =Inputs!$P$8-B34 -> 247.2365 | M34: =Inputs!$Q$8+L34*0.433 -> 1932.0534 | N34: =A34 -> 99099.92 | O34: =B34 -> 690.9545 | P34: =IF(O34="","",Inputs!$C$5-O34) -> 134.23 | Q34: =IF(N34="","",TS!J34) -> 2000 | R34: =IF(N34="","",TS!K34) -> 1825 | S34: =Inputs!$H$5+TS!P34*0.4333 -> 1933.1276 | T34: =Inputs!$G$5+TS!P34*0.4333 -> 1948.1276 | U34: =T34/(140000*C34/42) -> 0.97406379 | V34: =O34-MAX(O34:O177) -> -3.2414 | W34: =-(V34)*0.433 -> 1.4035262 | X34: =((PI()*((42-2*'Gen Calcs'!$E$13)^2)/4)/144)*(A77-#REF!)*(W34+14.7)/14.7 -> #REF! | Y34: =X34/1000 -> #REF! | Z34: =IF(Y34>Z33,Y34,Z33) -> #REF! | AA34: =MAX(B$2:B34)-B34 -> 134.23 | AB34: =AA34*0.433 -> 58.12159 | AC34: =((MAX(O$2:O$1348)-O34)-(MAX(O$2:O$1348)-O34))*0.433+AD34 -> 97.41123 | AD34: =(AD$2*AF$1391)/AG34 -> 97.41123 | AE34: =PI()*(((42-2*C34)/12)^2/4)*D34 -> 907.92028 | AF34: =SUM(AE$2:AE34) -> 29053.449 | AG34: =AF$1391-AF34 -> 1144676.5
A35: 99199.92 | B35: 691.3853 | C35: 0.6 | D35: =A35-A34 -> 100 | E35: =(PI()/4*(42/12-(2*C77/12))^2)*(D35)*7.48 -> 6791.2437 | F35: =SUM(E$2:E35) -> 223761.77 | G35: =IF(C35=0.72,12,IF(C35=1,11,IF(C35=0.825,10,IF(C35=0.6,1,IF(C35=0.864,2,IF(C35=0.888,3)))))) -> 1 | H35: 1 | I35: =C35 -> 0.6 | J35: =VLOOKUP(G35,Inputs!$L$3:$P$15,5,FALSE) -> 2000 | K35: =IF(H35=1,1825,IF(H35=2,1825,2220)) -> 1825 | L35: =Inputs!$P$8-B35 -> 246.8057 | M35: =Inputs!$Q$8+L35*0.433 -> 1931.8669 | N35: =A35 -> 99199.92 | O35: =B35 -> 691.3853 | P35: =IF(O35="","",Inputs!$C$5-O35) -> 133.7992 | Q35: =IF(N35="","",TS!J35) -> 2000 | R35: =IF(N35="","",TS!K35) -> 1825 | S35: =Inputs!$H$5+TS!P35*0.4333 -> 1932.9409 | T35: =Inputs!$G$5+TS!P35*0.4333 -> 1947.9409 | U35: =T35/(140000*C35/42) -> 0.97397045 | V35: =O35-MAX(O35:O177) -> -2.8106 | W35: =-(V35)*0.433 -> 1.2169898 | X35: =((PI()*((42-2*'Gen Calcs'!$E$13)^2)/4)/144)*(A78-#REF!)*(W35+14.7)/14.7 -> #REF! | Y35: =X35/1000 -> #REF! | Z35: =IF(Y35>Z34,Y35,Z34) -> #REF! | AA35: =MAX(B$2:B35)-B35 -> 133.7992 | AB35: =AA35*0.433 -> 57.935054 | AC35: =((MAX(O$2:O$1348)-O35)-(MAX(O$2:O$1348)-O35))*0.433+AD35 -> 97.488554 | AD35: =(AD$2*AF$1391)/AG35 -> 97.488554 | AE35: =PI()*(((42-2*C35)/12)^2/4)*D35 -> 907.92028 | AF35: =SUM(AE$2:AE35) -> 29961.369 | AG35: =AF$1391-AF35 -> 1143768.5
A36: 99299.92 | B36: 694.1959 | C36: 0.6 | D36: =A36-A35 -> 100 | E36: =(PI()/4*(42/12-(2*C78/12))^2)*(D36)*7.48 -> 6791.2437 | F36: =SUM(E$2:E36) -> 230553.01 | G36: =IF(C36=0.72,12,IF(C36=1,11,IF(C36=0.825,10,IF(C36=0.6,1,IF(C36=0.864,2,IF(C36=0.888,3)))))) -> 1 | H36: 1 | I36: =C36 -> 0.6 | J36: =VLOOKUP(G36,Inputs!$L$3:$P$15,5,FALSE) -> 2000 | K36: =IF(H36=1,1825,IF(H36=2,1825,2220)) -> 1825 | L36: =Inputs!$P$8-B36 -> 243.9951 | M36: =Inputs!$Q$8+L36*0.433 -> 1930.6499 | N36: =A36 -> 99299.92 | O36: =B36 -> 694.1959 | P36: =IF(O36="","",Inputs!$C$5-O36) -> 130.9886 | Q36: =IF(N36="","",TS!J36) -> 2000 | R36: =IF(N36="","",TS!K36) -> 1825 | S36: =Inputs!$H$5+TS!P36*0.4333 -> 1931.7231 | T36: =Inputs!$G$5+TS!P36*0.4333 -> 1946.7231 | U36: =T36/(140000*C36/42) -> 0.97336154 | V36: =O36-MAX(O36:O177) -> 0 | W36: =-(V36)*0.433 -> 0 | X36: =((PI()*((42-2*'Gen Calcs'!$E$13)^2)/4)/144)*(A79-#REF!)*(W36+14.7)/14.7 -> #REF! | Y36: =X36/1000 -> #REF! | Z36: =IF(Y36>Z35,Y36,Z35) -> #REF! | AA36: =MAX(B$2:B36)-B36 -> 130.9886 | AB36: =AA36*0.433 -> 56.718064 | AC36: =((MAX(O$2:O$1348)-O36)-(MAX(O$2:O$1348)-O36))*0.433+AD36 -> 97.566002 | AD36: =(AD$2*AF$1391)/AG36 -> 97.566002 | AE36: =PI()*(((42-2*C36)/12)^2/4)*D36 -> 907.92028 | AF36: =SUM(AE$2:AE36) -> 30869.289 | AG36: =AF$1391-AF36 -> 1142860.6
A37: 99399.92 | B37: 690.2778 | C37: 0.6 | D37: =A37-A36 -> 100 | E37: =(PI()/4*(42/12-(2*C79/12))^2)*(D37)*7.48 -> 6791.2437 | F37: =SUM(E$2:E37) -> 237344.26 | G37: =IF(C37=0.72,12,IF(C37=1,11,IF(C37=0.825,10,IF(C37=0.6,1,IF(C37=0.864,2,IF(C37=0.888,3)))))) -> 1 | H37: 1 | I37: =C37 -> 0.6 | J37: =VLOOKUP(G37,Inputs!$L$3:$P$15,5,FALSE) -> 2000 | K37: =IF(H37=1,1825,IF(H37=2,1825,2220)) -> 1825 | L37: =Inputs!$P$8-B37 -> 247.9132 | M37: =Inputs!$Q$8+L37*0.433 -> 1932.3464 | N37: =A37 -> 99399.92 | O37: =B37 -> 690.2778 | P37: =IF(O37="","",Inputs!$C$5-O37) -> 134.9067 | Q37: =IF(N37="","",TS!J37) -> 2000 | R37: =IF(N37="","",TS!K37) -> 1825 | S37: =Inputs!$H$5+TS!P37*0.4333 -> 1933.4208 | T37: =Inputs!$G$5+TS!P37*0.4333 -> 1948.4208 | U37: =T37/(140000*C37/42) -> 0.97421039 | V37: =O37-MAX(O37:O177) -> 0 | W37: =-(V37)*0.433 -> 0 | X37: =((PI()*((42-2*'Gen Calcs'!$E$13)^2)/4)/144)*(A80-#REF!)*(W37+14.7)/14.7 -> #REF! | Y37: =X37/1000 -> #REF! | Z37: =IF(Y37>Z36,Y37,Z36) -> #REF! | AA37: =MAX(B$2:B37)-B37 -> 134.9067 | AB37: =AA37*0.433 -> 58.414601 | AC37: =((MAX(O$2:O$1348)-O37)-(MAX(O$2:O$1348)-O37))*0.433+AD37 -> 97.643573 | AD37: =(AD$2*AF$1391)/AG37 -> 97.643573 | AE37: =PI()*(((42-2*C37)/12)^2/4)*D37 -> 907.92028 | AF37: =SUM(AE$2:AE37) -> 31777.21 | AG37: =AF$1391-AF37 -> 1141952.7
A38: 99499.92 | B38: 683.1334 | C38: 0.6 | D38: =A38-A37 -> 100 | E38: =(PI()/4*(42/12-(2*C80/12))^2)*(D38)*7.48 -> 6791.2437 | F38: =SUM(E$2:E38) -> 244135.5 | G38: =IF(C38=0.72,12,IF(C38=1,11,IF(C38=0.825,10,IF(C38=0.6,1,IF(C38=0.864,2,IF(C38=0.888,3)))))) -> 1 | H38: 1 | I38: =C38 -> 0.6 | J38: =VLOOKUP(G38,Inputs!$L$3:$P$15,5,FALSE) -> 2000 | K38: =IF(H38=1,1825,IF(H38=2,1825,2220)) -> 1825 | L38: =Inputs!$P$8-B38 -> 255.0576 | M38: =Inputs!$Q$8+L38*0.433 -> 1935.4399 | N38: =A38 -> 99499.92 | O38: =B38 -> 683.1334 | P38: =IF(O38="","",Inputs!$C$5-O38) -> 142.0511 | Q38: =IF(N38="","",TS!J38) -> 2000 | R38: =IF(N38="","",TS!K38) -> 1825 | S38: =Inputs!$H$5+TS!P38*0.4333 -> 1936.5165 | T38: =Inputs!$G$5+TS!P38*0.4333 -> 1951.5165 | U38: =T38/(140000*C38/42) -> 0.97575823 | V38: =O38-MAX(O38:O177) -> 0 | W38: =-(V38)*0.433 -> 0 | X38: =((PI()*((42-2*'Gen Calcs'!$E$13)^2)/4)/144)*(A81-#REF!)*(W38+14.7)/14.7 -> #REF! | Y38: =X38/1000 -> #REF! | Z38: =IF(Y38>Z37,Y38,Z37) -> #REF! | AA38: =MAX(B$2:B38)-B38 -> 142.0511 | AB38: =AA38*0.433 -> 61.508126 | AC38: =((MAX(O$2:O$1348)-O38)-(MAX(O$2:O$1348)-O38))*0.433+AD38 -> 97.721267 | AD38: =(AD$2*AF$1391)/AG38 -> 97.721267 | AE38: =PI()*(((42-2*C38)/12)^2/4)*D38 -> 907.92028 | AF38: =SUM(AE$2:AE38) -> 32685.13 | AG38: =AF$1391-AF38 -> 1141044.8
A39: 99596.6 | B39: 683.1334 | C39: 0.864 | D39: =A39-A38 -> 96.68 | E39: =(PI()/4*(42/12-(2*C81/12))^2)*(D39)*7.48 -> 6565.7744 | F39: =SUM(E$2:E39) -> 250701.27 | G39: =IF(C39=0.72,12,IF(C39=1,11,IF(C39=0.825,10,IF(C39=0.6,1,IF(C39=0.864,2,IF(C39=0.888,3)))))) -> 2 | H39: 1 | I39: =C39 -> 0.864 | J39: =VLOOKUP(G39,Inputs!$L$3:$P$15,5,FALSE) -> 2880 | K39: =IF(H39=1,1825,IF(H39=2,1825,2220)) -> 1825 | L39: =Inputs!$P$8-B39 -> 255.0576 | M39: =Inputs!$Q$8+L39*0.433 -> 1935.4399 | N39: =A39 -> 99596.6 | O39: =B39 -> 683.1334 | P39: =IF(O39="","",Inputs!$C$5-O39) -> 142.0511 | Q39: =IF(N39="","",TS!J39) -> 2880 | R39: =IF(N39="","",TS!K39) -> 1825 | S39: =Inputs!$H$5+TS!P39*0.4333 -> 1936.5165 | T39: =Inputs!$G$5+TS!P39*0.4333 -> 1951.5165 | U39: =T39/(140000*C39/42) -> 0.67760988 | V39: =O39-MAX(O39:O177) -> 0 | W39: =-(V39)*0.433 -> 0 | X39: =((PI()*((42-2*'Gen Calcs'!$E$13)^2)/4)/144)*(A82-#REF!)*(W39+14.7)/14.7 -> #REF! | Y39: =X39/1000 -> #REF! | Z39: =IF(Y39>Z38,Y39,Z38) -> #REF! | AA39: =MAX(B$2:B39)-B39 -> 142.0511 | AB39: =AA39*0.433 -> 61.508126 | AC39: =((MAX(O$2:O$1348)-O39)-(MAX(O$2:O$1348)-O39))*0.433+AD39 -> 97.794563 | AD39: =(AD$2*AF$1391)/AG39 -> 97.794563 | AE39: =PI()*(((42-2*C39)/12)^2/4)*D39 -> 855.20539 | AF39: =SUM(AE$2:AE39) -> 33540.335 | AG39: =AF$1391-AF39 -> 1140189.6
A40: 99599.92 | B40: 676.6292 | C40: 0.6 | D40: =A40-A39 -> 3.32 | E40: =(PI()/4*(42/12-(2*C82/12))^2)*(D40)*7.48 -> 225.46929 | F40: =SUM(E$2:E40) -> 250926.74 | G40: =IF(C40=0.72,12,IF(C40=1,11,IF(C40=0.825,10,IF(C40=0.6,1,IF(C40=0.864,2,IF(C40=0.888,3)))))) -> 1 | H40: 1 | I40: =C40 -> 0.6 | J40: =VLOOKUP(G40,Inputs!$L$3:$P$15,5,FALSE) -> 2000 | K40: =IF(H40=1,1825,IF(H40=2,1825,2220)) -> 1825 | L40: =Inputs!$P$8-B40 -> 261.5618 | M40: =Inputs!$Q$8+L40*0.433 -> 1938.2563 | N40: =A40 -> 99599.92 | O40: =B40 -> 676.6292 | P40: =IF(O40="","",Inputs!$C$5-O40) -> 148.5553 | Q40: =IF(N40="","",TS!J40) -> 2000 | R40: =IF(N40="","",TS!K40) -> 1825 | S40: =Inputs!$H$5+TS!P40*0.4333 -> 1939.3347 | T40: =Inputs!$G$5+TS!P40*0.4333 -> 1954.3347 | U40: =T40/(140000*C40/42) -> 0.97716736 | V40: =O40-MAX(O40:O177) -> 0 | W40: =-(V40)*0.433 -> 0 | X40: =((PI()*((42-2*'Gen Calcs'!$E$13)^2)/4)/144)*(A83-#REF!)*(W40+14.7)/14.7 -> #REF! | Y40: =X40/1000 -> #REF! | Z40: =IF(Y40>Z39,Y40,Z39) -> #REF! | AA40: =MAX(B$2:B40)-B40 -> 148.5553 | AB40: =AA40*0.433 -> 64.324445 | AC40: =((MAX(O$2:O$1348)-O40)-(MAX(O$2:O$1348)-O40))*0.433+AD40 -> 97.797149 | AD40: =(AD$2*AF$1391)/AG40 -> 97.797149 | AE40: =PI()*(((42-2*C40)/12)^2/4)*D40 -> 30.142953 | AF40: =SUM(AE$2:AE40) -> 33570.478 | AG40: =AF$1391-AF40 -> 1140159.4
...

Sheet Inputs
A1: Hugh Brinson Spread 5 Test Section 5
A2: Test Section 5 | B2: Station | C2: Elevation | F2: Location | G2: Max Pressure | H2: Min Pressure | I2: Static Head Pressure | L2: Maximum Pressure Based on SMYS
A3: Begin | B3: =TS!A2 -> 95899.92 | C3: =INDEX(TS!B2:B1391, MATCH(Inputs!B3,TS!A2:A1391,0),1) -> 825.1845 | D3: High Point | E3: =MAX(TS!B2:B1391) -> 938.191 | F3: =INDEX(TS!A2:A1391, MATCH(Inputs!E3,TS!B2:B1391,0),1) -> 162799.92 | G3: =VLOOKUP(F3,TS!N$2:S$1348,4,FALSE) -> 2000 | H3: =VLOOKUP(F3,TS!N$2:S$1348,5,FALSE) -> 1825 | I3: Fill | J3: Dewater | L3: Material | M3: W.T. | N3: Grade | O3: SMYS | P3: Max Press | Q3: Comments
A4: End | B4: =TS!A1391 -> 225299.92 | C4: =INDEX(TS!B2:B1391, MATCH(Inputs!B4,TS!A2:A1391,0),1) -> 757.0796 | D4: Low Point | E4: =MIN(TS!B2:B1391) -> 572.8108 | F4: =INDEX(TS!A2:A1391, MATCH(Inputs!E4,TS!B2:B1391,0),1) -> 116999.92 | G4: =VLOOKUP(F4,TS!N$2:S$1348,4,FALSE) -> 2000 | H4: =VLOOKUP(F4,TS!N$2:S$1348,5,FALSE) -> 1825 | I4: =(E3-C5)*0.4333 -> 48.965716 | J4: =(E3-C5)*0.4333 -> 48.965716 | L4: 1 | M4: 0.6 | N4: 70000 | O4: =2*N4*M4/42 -> 2000 | P4: =O4 -> 2000
A5: Test Site | B5: =B3 -> 95899.92 | C5: =INDEX(TS!B2:B1391, MATCH(Inputs!B5,TS!A2:A1391,0),1) -> 825.1845 | G5: =H5+15 -> 1889.9657 | H5: =H3+(E3-C5)*0.4333+1 -> 1874.9657 | I5: Test Headers | L5: 2 | M5: 0.864 | N5: 70000 | O5: =2*N5*M5/42 -> 2880 | P5: =O5 -> 2880
A6: Volume | B6: =TS!F1391 -> 8789611.9 | D6: Dewater Location | F6: =B4 -> 225299.92 | G6: Fill Site | H6: =B5 -> 95899.92 | I6: =IF(H5>2250, "MVP Headers", "Precision Headers") -> Precision Headers
P7: Elevation | Q7: Min Pressure
O8: High Point | P8: =MAX(TS!B2:B1479) -> 938.191 | Q8: {=INDEX(TS!K2:K1436, MATCH(Inputs!P8,TS!B2:B1479,0),0)} -> 1825
A9: User Defined Inputs. Note mileposts must be exact in order to calculate properly
A10: Calculations based on user defined inputs. Verify test site pressures fall within max/min
A11: Ensure Class Location Minimum Test Requirements are met
A12: ¹First tested section
A13: Max Head Pressure doesn't include backpressure and/or pressure required to propel dewatering pig
A14: Adjust based on pressure window desired
A16: Test Section 5
A17: Low Point Elevation | C17: =E4 -> 572.8108 | D17: Minimum | E17: =E$19+(C$19-C$17)*0.4333 -> 1984.3192 | F17: Maximum | G17: =G$19+(C$19-C$17)*0.4333 -> 1999.3192
A18: High Point Elevation | C18: =E3 -> 938.191 | D18: Minimum | E18: =E$19-(C$18-C$19)*0.4333 -> 1826 | F18: Maximum | G18: =G$19-(C$18-C$19)*0.4333 -> 1841
A19: Dead Weight Elevation | C19: =C5 -> 825.1845 | D19: Minimum | E19: =H5 -> 1874.9657 | F19: Maximum | G19: =G5 -> 1889.9657
A21: Section | B21: Start MP | C21: End MP | D21: Length | E21: Fill Volume | F21: Squeeze | G21: Total
A22: TS 5 | B22: =B3 -> 95899.92 | C22: =B4 -> 225299.92 | D22: =C22-B22 -> 129400 | E22: =B6 -> 8789611.9 | F22: =1.7*G5*D22/5280 -> 78741.413 | G22: =E22+F22 -> 8868353.3

Sheet Gen Calcs
B3: 1 (0.617"W, FBE) | C3: 34603.938 | D3: 0.617 | E3: =C3*D3 -> 21350.63
B4: 2 (0.740"W, FBE) | C4: 1729.081 | D4: 0.74 | E4: =C4*D4 -> 1279.5199
B5: 3 (0.888"W, FBE) | C5: 249.672 | D5: 0.888 | E5: =C5*D5 -> 221.70874
B6: 4 (0.740"W, FBE+ARO) | D6: 0.74 | E6: =C6*D6 -> 0
B7: 5 (0.888"W, FBE+ARO) | D7: 0.888 | E7: =C7*D7 -> 0
B8: 6 (0.617"W, FBE+ARO) | D8: 0.617 | E8: =C8*D8 -> 0
B9: 7 (ANSI 600 MIJ)
B10: 8 (ANSI 900 MIJ)
B11: 9 (0.888"W, Powercrete)
B12: Total | C12: =SUM(C3:C11) -> 36582.691 | E12: =SUM(E3:E11) -> 22851.858
C13: =C12-C9 -> 36582.691 | E13: =E12/C13 -> 0.62466313
B16: Air pressure
B17: Total Air required in 3 | C17: =TS!#REF!*1000 -> #REF!
B18: Transferred from Section 3 to 4 | C18: =TS!#REF!*1000 -> #REF!
B19: Total Air required in 4 | C19: =TS!#REF!*1000 -> #REF!
B20: Addl Air Required 4 after transfer from 3 | C20: =C19-C18 -> #REF!
B21: Transferred from Section 4 to 5 | C21: =C19 -> #REF!
B22: Total air required in 5 | C22: =TS!#REF!*1000 -> #REF!
B23: Addl Air Required 5 after transfer from 4 | C23: =C22-C21 -> #REF!
B24: Total air required in 6 | C24: =TS!#REF!*1000 -> #REF!
B25: Addl Air Required 6 after transfer from 5 | C25: =C24-C23 -> #REF!
B26: Total air required without transfer | C26: =C17+C19+C22+C24 -> #REF!
B27: Air required with transfer | C27: =C24 -> #REF!
B29: Vol/mi (gal) | C29: =((PI()*((42-2*'Gen Calcs'!$E$13)^2)/4)/144)*5280*7.48 -> 357711.17
B30: Vol/mi (ft3) | C30: =C29/7.48 -> 47822.348 | D30: MP
A31: 1&2 Fill | B31: T 1 & 2 backpressure max | C31: =MAX(TS!AD2:AD177) -> 108.69202 | D31: 74.82
B32: T 1 & 2 backpressure (2) | C32: =TS!#REF! -> #REF! | D32: 76.68
B33: T1 & T2 Pressure volume basis 1 start | C33: 239 | D33: 68.6
B34: T1 & T2 Pressure volume basis 1 end | C34: 343 | D34: 71.24
A35: 1&2 Dewater | B35: Max Air Volume | C35: =MAX(TS!#REF!) -> #REF! | D35: 68.66
B36: Air Input Rate SCFM | C36: 10000
B37: Air run time required (hours) | C37: =C35/C36/60 -> #REF!
B38: Calculated Dewater flow rate gpm (ave) | C38: =(Inputs!#REF!-'Gen Calcs'!D33)*'Gen Calcs'!C29/'Gen Calcs'!C37/60 -> #REF!
B39: Assumed Dewater Flow rate gpm (max) | C39: 5000
B40: Max Pig Speed (fpm) | C40: =C39/(C29/5280) -> 73.802561
B41: Max Pig speed (miles/min) | C41: =C40/5280 -> 0.013977758

Sheet Air calcs
A1: Time (min) | B1: SCF | C1: MP | D1: SCF reqd | E1: SCF min | F1: Air test 1 | G1: Air test 2 | H1: Pig location MP | I1: Elevation | J1: Water Backpressure (max) | K1: Air pressure (min) | L1: Water Volume discharged (gal) | M1: Water backpressure (min)
A2: 0 | B2: =A2*'Gen Calcs'!C$36 -> 0 | C2: =Inputs!B3 -> 95899.92 | D2: =VLOOKUP(C2,TS!N$2:Z$177,11,TRUE) -> #REF! | E2: =VLOOKUP(C2,TS!N$2:Z$177,13,TRUE)*1000 -> #REF! | F2: 0 | G2: 0 | H2: 77.13 | I2: =VLOOKUP('Air calcs'!C2,TS!N$2:O$177,2) -> 825.1845 | J2: 0 | K2: 0 | L2: 0 | M2: =(MAX(I1:I$206)-I$205)*0.433 -> #N/A
A3: 5 | B3: =A3*'Gen Calcs'!C$36 -> 50000 | C3: =C2-'Gen Calcs'!C$41*5 -> 95899.85 | D3: =VLOOKUP(C3,TS!N$2:Z$177,11,TRUE) -> #N/A | E3: =VLOOKUP(C3,TS!N$2:Z$177,13,TRUE)*1000 -> #N/A | F3: =IF(B3>D3,1,0) -> #N/A | G3: =IF(B3>E3,1,0) -> #N/A | H3: =IF(G3>0,H2-(5*'Gen Calcs'!C$41),'Air calcs'!H2) -> #N/A | I3: =VLOOKUP('Air calcs'!C3,TS!N$2:O$177,2) -> #N/A | J3: =((MAX(I3:I$205)-Inputs!C$3)-(MAX(I3:I$205)-I3))*0.433+K3 -> #N/A | K3: =14.7*B3/((C$2-C3)*'Gen Calcs'!C$29/7.48)-14.7 -> 205.212 | L3: =(H$2-H3)*'Gen Calcs'!C$29 -> #N/A | M3: =(MAX(I3:I$205)-I$205)*0.433 -> #N/A
A4: 10 | B4: =A4*'Gen Calcs'!C$36 -> 100000 | C4: =C3-'Gen Calcs'!C$41*5 -> 95899.78 | D4: =VLOOKUP(C4,TS!N$2:Z$177,11,TRUE) -> #N/A | E4: =VLOOKUP(C4,TS!N$2:Z$177,13,TRUE)*1000 -> #N/A | F4: =IF(B4>D4,1,0) -> #N/A | G4: =IF(B4>E4,1,0) -> #N/A | H4: =IF(G4>0,H3-(5*'Gen Calcs'!C$41),'Air calcs'!H3) -> #N/A | I4: =VLOOKUP('Air calcs'!C4,TS!N$2:O$177,2) -> #N/A | J4: =((MAX(I4:I$205)-Inputs!C$3)-(MAX(I4:I$205)-I4))*0.433+K4 -> #N/A | K4: =14.7*B4/((C$2-C4)*'Gen Calcs'!C$29/7.48)-14.7 -> 205.212 | L4: =(H$2-H4)*'Gen Calcs'!C$29 -> #N/A | M4: =(MAX(I4:I$205)-I$205)*0.433 -> #N/A
A5: 15 | B5: =A5*'Gen Calcs'!C$36 -> 150000 | C5: =H4 -> #N/A | D5: =VLOOKUP(C5,TS!N$2:Z$177,11,TRUE) -> #N/A | E5: =VLOOKUP(C5,TS!N$2:Z$177,13,TRUE)*1000 -> #N/A | F5: =IF(B5>D5,1,0) -> #N/A | G5: =IF(B5>E5,1,0) -> #N/A | H5: =IF(G5>0,H4-(5*'Gen Calcs'!C$41),'Air calcs'!H4) -> #N/A | I5: =VLOOKUP('Air calcs'!C5,TS!N$2:O$177,2) -> #N/A | J5: =((MAX(I5:I$205)-Inputs!C$3)-(MAX(I5:I$205)-I5))*0.433+K5 -> #N/A | K5: =14.7*B5/((C$2-C5)*'Gen Calcs'!C$29/7.48)-14.7 -> #N/A | L5: =(H$2-H5)*'Gen Calcs'!C$29 -> #N/A | M5: =(MAX(I5:I$205)-I$205)*0.433 -> #N/A
A6: 20 | B6: =A6*'Gen Calcs'!C$36 -> 200000 | C6: =H5 -> #N/A | D6: =VLOOKUP(C6,TS!N$2:Z$177,11,TRUE) -> #N/A | E6: =VLOOKUP(C6,TS!N$2:Z$177,13,TRUE)*1000 -> #N/A | F6: =IF(B6>D6,1,0) -> #N/A | G6: =IF(B6>E6,1,0) -> #N/A | H6: =IF(G6>0,H5-(5*'Gen Calcs'!C$41),'Air calcs'!H5) -> #N/A | I6: =VLOOKUP('Air calcs'!C6,TS!N$2:O$177,2) -> #N/A | J6: =((MAX(I6:I$205)-Inputs!C$3)-(MAX(I6:I$205)-I6))*0.433+K6 -> #N/A | K6: =14.7*B6/((C$2-C6)*'Gen Calcs'!C$29/7.48)-14.7 -> #N/A | L6: =(H$2-H6)*'Gen Calcs'!C$29 -> #N/A | M6: =(MAX(I6:I$205)-I$205)*0.433 -> #N/A
A7: 25 | B7: =A7*'Gen Calcs'!C$36 -> 250000 | C7: =H6 -> #N/A | D7: =VLOOKUP(C7,TS!N$2:Z$177,11,TRUE) -> #N/A | E7: =VLOOKUP(C7,TS!N$2:Z$177,13,TRUE)*1000 -> #N/A | F7: =IF(B7>D7,1,0) -> #N/A | G7: =IF(B7>E7,1,0) -> #N/A | H7: =IF(G7>0,H6-(5*'Gen Calcs'!C$41),'Air calcs'!H6) -> #N/A | I7: =VLOOKUP('Air calcs'!C7,TS!N$2:O$177,2) -> #N/A | J7: =((MAX(I7:I$205)-Inputs!C$3)-(MAX(I7:I$205)-I7))*0.433+K7 -> #N/A | K7: =14.7*B7/((C$2-C7)*'Gen Calcs'!C$29/7.48)-14.7 -> #N/A | L7: =(H$2-H7)*'Gen Calcs'!C$29 -> #N/A | M7: =(MAX(I7:I$205)-I$205)*0.433 -> #N/A
